Workbook

Sheet CLEANING
A1: Status | B1: A1 | C1: A2 | D1: A3 | E1: A4 | F1: A5 | G1: A6 | H1: A7 | I1: A8 | J1: A9 | K1: A10 | L1: A11 | M1: A12 | N1: A13 | O1: A14 | P1: A15 | Q1: A16 | R1: A17 | S1: A18 | T1: A19 | U1: A20 | V1: A21 | W1: A22 | X1: A23 | Y1: A24 | Z1: A25 | AA1: A26 | AB1: A27 | AC1: A28 | AD1: A29 | AE1: A30 | AF1: A31 | AG1: A32 | AH1: A33 | AI1: No
A2: YES | B2: 4 | C2: 1 | D2: 1 | E2: 6 | F2: 1 | G2: 2 | H2: 6 | I2: 2 | J2: 3 | K2: 5 | L2: 1 | M2: 2 | N2: 3 | O2: 1 | P2: 1 | Q2: 1 | R2: 2 | S2: 4 | T2: 2 | U2: 4 | V2: 2 | W2: 3 | X2: 2 | Y2: 4 | Z2: 2 | AA2: 3 | AB2: 2 | AC2: 4 | AD2: 2 | AE2: 4 | AF2: 1 | AG2: 4 | AH2: 2 | AI2: D1
A3: NO | B3: 3 | C3: 2 | D3: 2 | E3: 2 | F3: 1 | G3: 1 | H3: 6 | I3: 1 | J3: 2 | K3: 2 | L3: 1 | M3: 2 | N3: 3 | O3: 1 | P3: 1 | Q3: 1 | R3: 2 | S3: 3 | T3: 2 | U3: 4 | V3: 2 | W3: 3 | X3: 2 | Y3: 4 | Z3: 2 | AA3: 3 | AB3: 2 | AC3: 4 | AD3: 2 | AE3: 4 | AF3: 2 | AG3: 4 | AH3: 1 | AI3: D2
A4: NO | B4: 5 | C4: 2 | D4: 1.7435897 | E4: 6 | F4: 7 | G4: 1.835443 | H4: 10 | I4: 1.8481013 | J4: 2 | K4: 7 | L4: 2 | M4: 2.3108108 | N4: 3 | O4: 4 | P4: 1.1518987 | Q4: 3 | R4: 2 | S4: 4 | T4: 2 | U4: 4 | V4: 2 | W4: 4 | X4: 2 | Y4: 4 | Z4: 2 | AA4: 4 | AB4: 2 | AC4: 4 | AD4: 2 | AE4: 4 | AF4: 2 | AG4: 4 | AH4: 2 | AI4: D3
A5: NO | B5: 4 | C5: 1 | D5: 1 | E5: 8 | F5: 3 | G5: 2 | H5: 6 | I5: 2 | J5: 3 | K5: 11 | L5: 1 | M5: 1 | N5: 5 | O5: 1 | P5: 1 | Q5: 1 | R5: 2 | S5: 4 | T5: 2 | U5: 4 | V5: 2 | W5: 3 | X5: 2 | Y5: 4 | Z5: 1 | AA5: 4 | AB5: 2 | AC5: 4 | AD5: 2 | AE5: 4 | AF5: 1 | AG5: 4 | AH5: 2 | AI5: D4
A6: YES | B6: 5 | C6: 2 | D6: 2 | E6: 6 | F6: 1 | G6: 2 | H6: 6 | I6: 2 | J6: 1 | K6: 2 | L6: 1 | M6: 1 | N6: 5 | O6: 1 | P6: 1 | Q6: 1 | R6: 2 | S6: 3 | T6: 2 | U6: 4 | V6: 2 | W6: 3 | X6: 2 | Y6: 4 | Z6: 2 | AA6: 3 | AB6: 2 | AC6: 4 | AD6: 2 | AE6: 4 | AF6: 2 | AG6: 4 | AH6: 2 | AI6: D5
A7: NO | B7: 5 | C7: 2 | D7: 2 | E7: 6 | F7: 1 | G7: 2 | H7: 6 | I7: 2 | J7: 1 | K7: 2 | L7: 1 | M7: 2 | N7: 2 | O7: 1 | P7: 1 | Q7: 1 | R7: 1 | S7: 3 | T7: 2 | U7: 4 | V7: 2 | W7: 3 | X7: 2 | Y7: 4 | Z7: 1 | AA7: 3 | AB7: 2 | AC7: 4 | AD7: 2 | AE7: 4 | AF7: 2 | AG7: 4 | AH7: 1 | AI7: D6
A8: NO | B8: 5 | C8: 1 | D8: 1 | E8: 8 | F8: 3 | G8: 2 | H8: 6 | I8: 2 | J8: 4 | K8: 2 | L8: 1 | M8: 6 | N8: 3 | O8: 1 | P8: 1 | Q8: 1 | R8: 2 | S8: 4 | T8: 2 | U8: 4 | V8: 2 | W8: 3 | X8: 2 | Y8: 4 | Z8: 2 | AA8: 4 | AB8: 2 | AC8: 4 | AD8: 2 | AE8: 4 | AF8: 1 | AG8: 4 | AH8: 1 | AI8: D7
A9: NO | B9: 6 | C9: 1 | D9: 4 | E9: 8 | F9: 3 | G9: 2 | H9: 6 | I9: 2 | J9: 2 | K9: 2 | L9: 1 | M9: 2 | N9: 3 | O9: 1 | P9: 1 | Q9: 1 | R9: 2 | S9: 3 | T9: 2 | U9: 4 | V9: 2 | W9: 3 | X9: 2 | Y9: 4 | Z9: 2 | AA9: 3 | AB9: 2 | AC9: 4 | AD9: 2 | AE9: 4 | AF9: 2 | AG9: 4 | AH9: 1 | AI9: D8
A10: NO | B10: 2 | C10: 1.55 | D10: 1.7435897 | E10: 5.025 | F10: 1.625 | G10: 1.835443 | H10: 5.9875 | I10: 1.8481013 | J10: 2.1139241 | K10: 3.175 | L10: 1.1 | M10: 2.3108108 | N10: 3.0625 | O10: 1.225 | P10: 1.1518987 | Q10: 1.4 | R10: 1.9382716 | S10: 3.382716 | T10: 1.962963 | U10: 4 | V10: 2 | W10: 3.1234568 | X10: 1.962963 | Y10: 3.9506173 | Z10: 1.7530864 | AA10: 3.3580247 | AB10: 1.9876543 | AC10: 4 | AD10: 1.9753086 | AE10: 4 | AF10: 1.4625 | AG10: 4 | AH10: 1.7922078 | AI10: D9
A11: YES | B11: 3 | C11: 1.55 | D11: 1.7435897 | E11: 5.025 | F11: 1.625 | G11: 1.835443 | H11: 5.9875 | I11: 1.8481013 | J11: 2.1139241 | K11: 3.175 | L11: 1.1 | M11: 2.3108108 | N11: 3.0625 | O11: 1.225 | P11: 1.1518987 | Q11: 1.4 | R11: 1.9382716 | S11: 3.382716 | T11: 1.962963 | U11: 4 | V11: 2 | W11: 3.1234568 | X11: 1.962963 | Y11: 3.9506173 | Z11: 1.7530864 | AA11: 3.3580247 | AB11: 1.9876543 | AC11: 4 | AD11: 1.9753086 | AE11: 4 | AF11: 1.4625 | AG11: 4 | AH11: 1.7922078 | AI11: D10
A12: YES | B12: 7 | C12: 1 | D12: 1 | E12: 2 | F12: 1 | G12: 2 | H12: 6 | I12: 2 | J12: 3 | K12: 2 | L12: 1 | M12: 2 | N12: 3 | O12: 1 | P12: 1 | Q12: 1 | R12: 2 | S12: 3 | T12: 2 | U12: 4 | V12: 2 | W12: 3 | X12: 2 | Y12: 4 | Z12: 2 | AA12: 3 | AB12: 2 | AC12: 4 | AD12: 2 | AE12: 4 | AF12: 1 | AG12: 4 | AH12: 2 | AI12: D11
A13: NO | B13: 4 | C13: 1 | D13: 1 | E13: 2 | F13: 1 | G13: 2 | H13: 6 | I13: 2 | J13: 3 | K13: 2 | L13: 1 | M13: 2 | N13: 3 | O13: 1 | P13: 1 | Q13: 1 | R13: 2 | S13: 3 | T13: 2 | U13: 4 | V13: 2 | W13: 3 | X13: 2 | Y13: 4 | Z13: 2 | AA13: 3 | AB13: 2 | AC13: 4 | AD13: 2 | AE13: 4 | AF13: 1 | AG13: 4 | AH13: 2 | AI13: D12
... A21: YES | B21: 3 | C21: 1 | D21: 1 | E21: 6 | F21: 1 | G21: 2 | H21: 6 | I21: 2 | J21: 3 | K21: 2 | L21: 1 | M21: 2 | N21: 3 | O21: 1 | P21: 1 | Q21: 1 | R21: 2 | S21: 4 | T21: 2 | U21: 4 | V21: 2 | W21: 3 | X21: 2 | Y21: 4 | Z21: 2 | AA21: 4 | AB21: 2 | AC21: 4 | AD21: 2 | AE21: 4 | AF21: 1 | AG21: 4 | AH21: 2 | AI21: D20

Sheet NORMALISASI
A1: STATUS | B1: A1 | C1: A2 | D1: A3 | E1: A4 | F1: A5 | G1: A6 | H1: A7 | I1: A8 | J1: A9 | K1: A10 | L1: A11 | M1: A12 | N1: A13 | O1: A14 | P1: A15 | Q1: A16 | R1: A17 | S1: A18 | T1: A19 | U1: A20 | V1: A21 | W1: A22 | X1: A23 | Y1: A24 | Z1: A25 | AA1: A26 | AB1: A27 | AC1: A28 | AD1: A29 | AE1: A30 | AF1: A31 | AG1: A32 | AH1: A33
A2: YES | B2: 0.7 | C2: 0.2 | D2: 0.3 | E2: 0.7 | F2: 0.3 | G2: 1 | H2: 0.5 | I2: 1 | J2: 0.2 | K2: 0 | L2: 0 | M2: 0.2 | N2: 0.5 | O2: 0 | P2: 0 | Q2: 0 | R2: 1 | S2: 0 | T2: 1 | U2: 1 | V2: 1 | W2: 0 | X2: 1 | Y2: 1 | Z2: 1 | AA2: 0 | AB2: 1 | AC2: 1 | AD2: 1 | AE2: 1 | AF2: 1 | AG2: 1 | AH2: 0.5
A3: NO | B3: 0.5 | C3: 0.1 | D3: 0.2 | E3: 0.5 | F3: 0.1 | G3: 0.9 | H3: 0.55416667 | I3: 0.84810127 | J3: 0.42278481 | K3: 0.13055556 | L3: 0.05 | M3: 0.26216216 | N3: 0.515625 | O3: 0.075 | P3: 0.050632911 | Q3: 0.1 | R3: 0.9382716 | S3: 0.38271605 | T3: 0.96296296 | U3: 1 | V3: 1 | W3: 0.12345679 | X3: 0.96296296 | Y3: 0.95061728 | Z3: 0.75308642 | AA3: 0.35802469 | AB3: 0.98765432 | AC3: 1 | AD3: 0.97530864 | AE3: 1 | AF3: 0.4625 | AG3: 1 | AH3: 0.8961039
A4: NO | B4: 0 | C4: 0.1 | D4: 0.2 | E4: 0.5 | F4: 0.1 | G4: 0.9 | H4: 0.55416667 | I4: 0.84810127 | J4: 0.42278481 | K4: 0.13055556 | L4: 0.05 | M4: 0.26216216 | N4: 0.515625 | O4: 0.075 | P4: 0.050632911 | Q4: 0.1 | R4: 0.9382716 | S4: 0.38271605 | T4: 0.96296296 | U4: 1 | V4: 1 | W4: 0.12345679 | X4: 0.96296296 | Y4: 0.95061728 | Z4: 0.75308642 | AA4: 0.35802469 | AB4: 0.98765432 | AC4: 1 | AD4: 0.97530864 | AE4: 1 | AF4: 0.4625 | AG4: 1 | AH4: 0.8961039
A5: NO | B5: 0 | C5: 0.1 | D5: 0.2 | E5: 0.5 | F5: 0.1 | G5: 0.9 | H5: 0.55416667 | I5: 0.84810127 | J5: 0.42278481 | K5: 0.13055556 | L5: 0.05 | M5: 0.26216216 | N5: 0.515625 | O5: 0.075 | P5: 0.050632911 | Q5: 0.1 | R5: 0.9382716 | S5: 0.38271605 | T5: 0.96296296 | U5: 1 | V5: 1 | W5: 0.12345679 | X5: 0.96296296 | Y5: 0.95061728 | Z5: 0.75308642 | AA5: 0.35802469 | AB5: 0.98765432 | AC5: 1 | AD5: 0.97530864 | AE5: 1 | AF5: 0.4625 | AG5: 1 | AH5: 0.8961039
A6: NO | B6: 0 | C6: 0.1 | D6: 0.2 | E6: 0.5 | F6: 0.1 | G6: 0.9 | H6: 0.55416667 | I6: 0.84810127 | J6: 0.42278481 | K6: 0.13055556 | L6: 0.05 | M6: 0.26216216 | N6: 0.515625 | O6: 0.075 | P6: 0.050632911 | Q6: 0.1 | R6: 0.9382716 | S6: 0.38271605 | T6: 0.96296296 | U6: 1 | V6: 1 | W6: 0.12345679 | X6: 0.96296296 | Y6: 0.95061728 | Z6: 0.75308642 | AA6: 0.35802469 | AB6: 0.98765432 | AC6: 1 | AD6: 0.97530864 | AE6: 1 | AF6: 0.4625 | AG6: 1 | AH6: 0.8961039
A7: NO | B7: 0 | C7: 0.1 | D7: 0.2 | E7: 0.5 | F7: 0.1 | G7: 0.9 | H7: 0.55416667 | I7: 0.84810127 | J7: 0.42278481 | K7: 0.13055556 | L7: 0.05 | M7: 0.26216216 | N7: 0.515625 | O7: 0.075 | P7: 0.050632911 | Q7: 0.1 | R7: 0.9382716 | S7: 0.38271605 | T7: 0.96296296 | U7: 1 | V7: 1 | W7: 0.12345679 | X7: 0.96296296 | Y7: 0.95061728 | Z7: 0.75308642 | AA7: 0.35802469 | AB7: 0.98765432 | AC7: 1 | AD7: 0.97530864 | AE7: 1 | AF7: 0.4625 | AG7: 1 | AH7: 0.8961039
A8: NO | B8: 0.5 | C8: 0.2 | D8: 0.3 | E8: 0.7 | F8: 0.3 | G8: 1 | H8: 0.5 | I8: 1 | J8: 0.2 | K8: 0 | L8: 0 | M8: 0.2 | N8: 0.5 | O8: 0 | P8: 0 | Q8: 0 | R8: 1 | S8: 0 | T8: 1 | U8: 1 | V8: 1 | W8: 0 | X8: 1 | Y8: 1 | Z8: 1 | AA8: 0 | AB8: 1 | AC8: 1 | AD8: 1 | AE8: 1 | AF8: 1 | AG8: 1 | AH8: 1
A9: NO | B9: 0 | C9: 0.1 | D9: 0.2 | E9: 0.5 | F9: 0.1 | G9: 0.9 | H9: 0.55416667 | I9: 0.84810127 | J9: 0.42278481 | K9: 0.13055556 | L9: 0.05 | M9: 0.26216216 | N9: 0.515625 | O9: 0.075 | P9: 0.050632911 | Q9: 0.1 | R9: 0.9382716 | S9: 0.38271605 | T9: 0.96296296 | U9: 1 | V9: 1 | W9: 0.12345679 | X9: 0.96296296 | Y9: 0.95061728 | Z9: 0.75308642 | AA9: 0.35802469 | AB9: 0.98765432 | AC9: 1 | AD9: 0.97530864 | AE9: 1 | AF9: 0.4625 | AG9: 1 | AH9: 0.8961039
A10: NO | B10: 0.2 | C10: 0 | D10: 0 | E10: 0 | F10: 0 | G10: 1 | H10: 0.5 | I10: 1 | J10: 0.4 | K10: 1 | L10: 0 | M10: 0 | N10: 0.5 | O10: 0 | P10: 0 | Q10: 0 | R10: 1 | S10: 1 | T10: 1 | U10: 1 | V10: 1 | W10: 1 | X10: 1 | Y10: 1 | Z10: 0 | AA10: 1 | AB10: 1 | AC10: 1 | AD10: 1 | AE10: 1 | AF10: 0 | AG10: 1 | AH10: 1
A11: YES | B11: 0.5 | C11: 0 | D11: 0 | E11: 1 | F11: 0.3 | G11: 1 | H11: 0.5 | I11: 1 | J11: 0.4 | K11: 0 | L11: 0 | M11: 0.2 | N11: 0.5 | O11: 0 | P11: 0 | Q11: 0 | R11: 1 | S11: 1 | T11: 1 | U11: 1 | V11: 1 | W11: 0 | X11: 1 | Y11: 1 | Z11: 1 | AA11: 0 | AB11: 1 | AC11: 1 | AD11: 1 | AE11: 1 | AF11: 0 | AG11: 1 | AH11: 1
A12: NO | B12: 0.5 | C12: 0.2 | D12: 0.3 | E12: 0.7 | F12: 0 | G12: 1 | H12: 0.5 | I12: 1 | J12: 0.2 | K12: 0 | L12: 0 | M12: 1 | N12: 0.5 | O12: 0.3 | P12: 0 | Q12: 0 | R12: 1 | S12: 0 | T12: 1 | U12: 1 | V12: 1 | W12: 0 | X12: 1 | Y12: 1 | Z12: 0 | AA12: 0 | AB12: 1 | AC12: 1 | AD12: 1 | AE12: 1 | AF12: 1 | AG12: 1 | AH12: 1
A13: NO | B13: 0.5 | C13: 0.2 | D13: 0.3 | E13: 0.7 | F13: 0 | G13: 1 | H13: 0.5 | I13: 1 | J13: 0.4 | K13: 0 | L13: 0 | M13: 1 | N13: 1 | O13: 0.3 | P13: 0 | Q13: 0 | R13: 1 | S13: 1 | T13: 1 | U13: 1 | V13: 1 | W13: 0 | X13: 1 | Y13: 1 | Z13: 1 | AA13: 1 | AB13: 1 | AC13: 1 | AD13: 1 | AE13: 1 | AF13: 1 | AG13: 1 | AH13: 1
... A21: YES | B21: 0.5 | C21: 0 | D21: 0 | E21: 0.7 | F21: 0.3 | G21: 1 | H21: 0.5 | I21: 0 | J21: 0.2 | K21: 0.44444444 | L21: 1 | M21: 0.26216216 | N21: 0.5 | O21: 1 | P21: 1 | Q21: 0.75 | R21: 1 | S21: 1 | T21: 1 | U21: 1 | V21: 1 | W21: 1 | X21: 1 | Y21: 1 | Z21: 1 | AA21: 1 | AB21: 1 | AC21: 1 | AD21: 1 | AE21: 1 | AF21: 1 | AG21: 1 | AH21: 0

Sheet DATA TRAINING
A1: STATUS | B1: A1 | C1: A2 | D1: A3 | E1: A4 | F1: A5 | G1: A6 | H1: A7 | I1: A8 | J1: A9 | K1: A10 | L1: A11 | M1: A12 | N1: A13 | O1: A14 | P1: A15 | Q1: A16 | R1: A17 | S1: A18 | T1: A19 | U1: A20 | V1: A21 | W1: A22 | X1: A23 | Y1: A24 | Z1: A25 | AA1: A26 | AB1: A27 | AC1: A28 | AD1: A29 | AE1: A30 | AF1: A31 | AG1: A32 | AH1: A33
A2: YES | B2: 0.7 | C2: 0.2 | D2: 0.3 | E2: 0.7 | F2: 0.3 | G2: 1 | H2: 0.5 | I2: 1 | J2: 0.2 | K2: 0 | L2: 0 | M2: 0.2 | N2: 0.5 | O2: 0 | P2: 0 | Q2: 0 | R2: 1 | S2: 0 | T2: 1 | U2: 1 | V2: 1 | W2: 0 | X2: 1 | Y2: 1 | Z2: 1 | AA2: 0 | AB2: 1 | AC2: 1 | AD2: 1 | AE2: 1 | AF2: 1 | AG2: 1 | AH2: 0.5
A3: NO | B3: 0.5 | C3: 0.1 | D3: 0.2 | E3: 0.5 | F3: 0.1 | G3: 0.9 | H3: 0.55416667 | I3: 0.84810127 | J3: 0.42278481 | K3: 0.13055556 | L3: 0.05 | M3: 0.26216216 | N3: 0.515625 | O3: 0.075 | P3: 0.050632911 | Q3: 0.1 | R3: 0.9382716 | S3: 0.38271605 | T3: 0.96296296 | U3: 1 | V3: 1 | W3: 0.12345679 | X3: 0.96296296 | Y3: 0.95061728 | Z3: 0.75308642 | AA3: 0.35802469 | AB3: 0.98765432 | AC3: 1 | AD3: 0.97530864 | AE3: 1 | AF3: 0.4625 | AG3: 1 | AH3: 0.8961039
A4: NO | B4: 0 | C4: 0.1 | D4: 0.2 | E4: 0.5 | F4: 0.1 | G4: 0.9 | H4: 0.55416667 | I4: 0.84810127 | J4: 0.42278481 | K4: 0.13055556 | L4: 0.05 | M4: 0.26216216 | N4: 0.515625 | O4: 0.075 | P4: 0.050632911 | Q4: 0.1 | R4: 0.9382716 | S4: 0.38271605 | T4: 0.96296296 | U4: 1 | V4: 1 | W4: 0.12345679 | X4: 0.96296296 | Y4: 0.95061728 | Z4: 0.75308642 | AA4: 0.35802469 | AB4: 0.98765432 | AC4: 1 | AD4: 0.97530864 | AE4: 1 | AF4: 0.4625 | AG4: 1 | AH4: 0.8961039
A5: NO | B5: 0 | C5: 0.1 | D5: 0.2 | E5: 0.5 | F5: 0.1 | G5: 0.9 | H5: 0.55416667 | I5: 0.84810127 | J5: 0.42278481 | K5: 0.13055556 | L5: 0.05 | M5: 0.26216216 | N5: 0.515625 | O5: 0.075 | P5: 0.050632911 | Q5: 0.1 | R5: 0.9382716 | S5: 0.38271605 | T5: 0.96296296 | U5: 1 | V5: 1 | W5: 0.12345679 | X5: 0.96296296 | Y5: 0.95061728 | Z5: 0.75308642 | AA5: 0.35802469 | AB5: 0.98765432 | AC5: 1 | AD5: 0.97530864 | AE5: 1 | AF5: 0.4625 | AG5: 1 | AH5: 0.8961039
A6: NO | B6: 0 | C6: 0.1 | D6: 0.2 | E6: 0.5 | F6: 0.1 | G6: 0.9 | H6: 0.55416667 | I6: 0.84810127 | J6: 0.42278481 | K6: 0.13055556 | L6: 0.05 | M6: 0.26216216 | N6: 0.515625 | O6: 0.075 | P6: 0.050632911 | Q6: 0.1 | R6: 0.9382716 | S6: 0.38271605 | T6: 0.96296296 | U6: 1 | V6: 1 | W6: 0.12345679 | X6: 0.96296296 | Y6: 0.95061728 | Z6: 0.75308642 | AA6: 0.35802469 | AB6: 0.98765432 | AC6: 1 | AD6: 0.97530864 | AE6: 1 | AF6: 0.4625 | AG6: 1 | AH6: 0.8961039
A7: NO | B7: 0 | C7: 0.1 | D7: 0.2 | E7: 0.5 | F7: 0.1 | G7: 0.9 | H7: 0.55416667 | I7: 0.84810127 | J7: 0.42278481 | K7: 0.13055556 | L7: 0.05 | M7: 0.26216216 | N7: 0.515625 | O7: 0.075 | P7: 0.050632911 | Q7: 0.1 | R7: 0.9382716 | S7: 0.38271605 | T7: 0.96296296 | U7: 1 | V7: 1 | W7: 0.12345679 | X7: 0.96296296 | Y7: 0.95061728 | Z7: 0.75308642 | AA7: 0.35802469 | AB7: 0.98765432 | AC7: 1 | AD7: 0.97530864 | AE7: 1 | AF7: 0.4625 | AG7: 1 | AH7: 0.8961039

Sheet DATA TESTING
A1: STATUS | B1: A1 | C1: A2 | D1: A3 | E1: A4 | F1: A5 | G1: A6 | H1: A7 | I1: A8 | J1: A9 | K1: A10 | L1: A11 | M1: A12 | N1: A13 | O1: A14 | P1: A15 | Q1: A16 | R1: A17 | S1: A18 | T1: A19 | U1: A20 | V1: A21 | W1: A22 | X1: A23 | Y1: A24 | Z1: A25 | AA1: A26 | AB1: A27 | AC1: A28 | AD1: A29 | AE1: A30 | AF1: A31 | AG1: A32 | AH1: A33
A2: NO | B2: 0.5 | C2: 0.2 | D2: 0.3 | E2: 0.7 | F2: 0.3 | G2: 1 | H2: 0.5 | I2: 1 | J2: 0.2 | K2: 0 | L2: 0 | M2: 0.2 | N2: 0.5 | O2: 0 | P2: 0 | Q2: 0 | R2: 1 | S2: 0 | T2: 1 | U2: 1 | V2: 1 | W2: 0 | X2: 1 | Y2: 1 | Z2: 1 | AA2: 0 | AB2: 1 | AC2: 1 | AD2: 1 | AE2: 1 | AF2: 1 | AG2: 1 | AH2: 1
A3: NO | B3: 0 | C3: 0.1 | D3: 0.2 | E3: 0.5 | F3: 0.1 | G3: 0.9 | H3: 0.55416667 | I3: 0.84810127 | J3: 0.42278481 | K3: 0.13055556 | L3: 0.05 | M3: 0.26216216 | N3: 0.515625 | O3: 0.075 | P3: 0.050632911 | Q3: 0.1 | R3: 0.9382716 | S3: 0.38271605 | T3: 0.96296296 | U3: 1 | V3: 1 | W3: 0.12345679 | X3: 0.96296296 | Y3: 0.95061728 | Z3: 0.75308642 | AA3: 0.35802469 | AB3: 0.98765432 | AC3: 1 | AD3: 0.97530864 | AE3: 1 | AF3: 0.4625 | AG3: 1 | AH3: 0.8961039
A4: NO | B4: 0.2 | C4: 0 | D4: 0 | E4: 0 | F4: 0 | G4: 1 | H4: 0.5 | I4: 1 | J4: 0.4 | K4: 1 | L4: 0 | M4: 0 | N4: 0.5 | O4: 0 | P4: 0 | Q4: 0 | R4: 1 | S4: 1 | T4: 1 | U4: 1 | V4: 1 | W4: 1 | X4: 1 | Y4: 1 | Z4: 0 | AA4: 1 | AB4: 1 | AC4: 1 | AD4: 1 | AE4: 1 | AF4: 0 | AG4: 1 | AH4: 1
A5: YES | B5: 0.5 | C5: 0 | D5: 0 | E5: 1 | F5: 0.3 | G5: 1 | H5: 0.5 | I5: 1 | J5: 0.4 | K5: 0 | L5: 0 | M5: 0.2 | N5: 0.5 | O5: 0 | P5: 0 | Q5: 0 | R5: 1 | S5: 1 | T5: 1 | U5: 1 | V5: 1 | W5: 0 | X5: 1 | Y5: 1 | Z5: 1 | AA5: 0 | AB5: 1 | AC5: 1 | AD5: 1 | AE5: 1 | AF5: 0 | AG5: 1 | AH5: 1

Sheet NBC
A1: HO: 60% : 40 % yaitu 60% data treining dan 40% data testing. Menggunakan linear sampling
A3: NO | B3: A1 | C3: A2 | D3: A3 | E3: A4 | F3: A5 | G3: A6 | H3: A7 | I3: A8 | J3: A9 | K3: A10 | L3: A11 | M3: A12 | N3: A13 | O3: A14 | P3: A15 | Q3: A16 | R3: A17 | S3: A18 | T3: A19 | U3: A20 | V3: A21 | W3: A22 | X3: A23 | Y3: A24 | Z3: A25 | AA3: A26 | AB3: A27 | AC3: A28 | AD3: A29 | AE3: A30 | AF3: A31 | AG3: A32 | AH3: A33 | AI3: STATUS
A4: D1 | B4: 0.5 | C4: 0 | D4: 0 | E4: 0.7 | F4: 0 | G4: 1 | H4: 0.5 | I4: 1 | J4: 0.6 | K4: 0.3 | L4: 0 | M4: 0.2 | N4: 0.5 | O4: 0 | P4: 0 | Q4: 0 | R4: 1 | S4: 1 | T4: 1 | U4: 1 | V4: 1 | W4: 0 | X4: 1 | Y4: 1 | Z4: 1 | AA4: 0 | AB4: 1 | AC4: 1 | AD4: 1 | AE4: 1 | AF4: 0 | AG4: 1 | AH4: 1 | AI4: YES
A5: D2 | B5: 0.3 | C5: 0.2 | D5: 0.3 | E5: 0 | F5: 0 | G5: 0 | H5: 0.5 | I5: 0 | J5: 0.4 | K5: 0 | L5: 0 | M5: 0.2 | N5: 0.5 | O5: 0 | P5: 0 | Q5: 0 | R5: 1 | S5: 0 | T5: 1 | U5: 1 | V5: 1 | W5: 0 | X5: 1 | Y5: 1 | Z5: 1 | AA5: 0 | AB5: 1 | AC5: 1 | AD5: 1 | AE5: 1 | AF5: 1 | AG5: 1 | AH5: 0.5 | AI5: NO
A6: D3 | B6: 0.7 | C6: 0.2 | D6: 0.2 | E6: 0.7 | F6: 1 | G6: 0.9 | H6: 1 | I6: 0.84810127 | J6: 0.4 | K6: 0.5 | L6: 0.5 | M6: 0.26216216 | N6: 0.5 | O6: 1 | P6: 0.050632911 | Q6: 0.5 | R6: 1 | S6: 1 | T6: 1 | U6: 1 | V6: 1 | W6: 1 | X6: 1 | Y6: 1 | Z6: 1 | AA6: 1 | AB6: 1 | AC6: 1 | AD6: 1 | AE6: 1 | AF6: 1 | AG6: 1 | AH6: 1 | AI6: NO
A7: D4 | B7: 0.5 | C7: 0 | D7: 0 | E7: 1 | F7: 0.3 | G7: 1 | H7: 0.5 | I7: 1 | J7: 0.6 | K7: 1 | L7: 0 | M7: 0 | N7: 1 | O7: 0 | P7: 0 | Q7: 0 | R7: 1 | S7: 1 | T7: 1 | U7: 1 | V7: 1 | W7: 0 | X7: 1 | Y7: 1 | Z7: 0 | AA7: 1 | AB7: 1 | AC7: 1 | AD7: 1 | AE7: 1 | AF7: 0 | AG7: 1 | AH7: 1 | AI7: NO
A8: D5 | B8: 0.7 | C8: 0.2 | D8: 0.3 | E8: 0.7 | F8: 0 | G8: 1 | H8: 0.5 | I8: 1 | J8: 0.2 | K8: 0 | L8: 0 | M8: 0 | N8: 1 | O8: 0 | P8: 0 | Q8: 0 | R8: 1 | S8: 0 | T8: 1 | U8: 1 | V8: 1 | W8: 0 | X8: 1 | Y8: 1 | Z8: 1 | AA8: 0 | AB8: 1 | AC8: 1 | AD8: 1 | AE8: 1 | AF8: 1 | AG8: 1 | AH8: 1 | AI8: YES
A9: D6 | B9: 0.7 | C9: 0.2 | D9: 0.3 | E9: 0.7 | F9: 0 | G9: 1 | H9: 0.5 | I9: 1 | J9: 0.2 | K9: 0 | L9: 0 | M9: 0.2 | N9: 0.2 | O9: 0 | P9: 0 | Q9: 0 | R9: 0 | S9: 0 | T9: 1 | U9: 1 | V9: 1 | W9: 0 | X9: 1 | Y9: 1 | Z9: 0 | AA9: 0 | AB9: 1 | AC9: 1 | AD9: 1 | AE9: 1 | AF9: 1 | AG9: 1 | AH9: 0.5 | AI9: NO
A10: D7 | B10: 0.7 | C10: 0 | D10: 0 | E10: 1 | F10: 0.3 | G10: 1 | H10: 0.5 | I10: 1 | J10: 0.8 | K10: 0 | L10: 0 | M10: 1 | N10: 0.5 | O10: 0 | P10: 0 | Q10: 0 | R10: 1 | S10: 1 | T10: 1 | U10: 1 | V10: 1 | W10: 0 | X10: 1 | Y10: 1 | Z10: 1 | AA10: 1 | AB10: 1 | AC10: 1 | AD10: 1 | AE10: 1 | AF10: 0 | AG10: 1 | AH10: 0.5 | AI10: NO
A11: D8 | B11: 0.9 | C11: 0 | D11: 1 | E11: 1 | F11: 0.3 | G11: 1 | H11: 0.5 | I11: 1 | J11: 0.4 | K11: 0 | L11: 0 | M11: 0.2 | N11: 0.5 | O11: 0 | P11: 0 | Q11: 0 | R11: 1 | S11: 0 | T11: 1 | U11: 1 | V11: 1 | W11: 0 | X11: 1 | Y11: 1 | Z11: 1 | AA11: 0 | AB11: 1 | AC11: 1 | AD11: 1 | AE11: 1 | AF11: 1 | AG11: 1 | AH11: 0.5 | AI11: NO
A12: D9 | B12: 0.2 | C12: 0.1 | D12: 0.2 | E12: 0.5 | F12: 0.1 | G12: 0.9 | H12: 0.55416667 | I12: 0.84810127 | J12: 0.42278481 | K12: 0.13055556 | L12: 0.05 | M12: 0.26216216 | N12: 0.515625 | O12: 0.075 | P12: 0.050632911 | Q12: 0.1 | R12: 0.9382716 | S12: 0.38271605 | T12: 0.96296296 | U12: 1 | V12: 1 | W12: 0.12345679 | X12: 0.96296296 | Y12: 0.95061728 | Z12: 0.75308642 | AA12: 0.35802469 | AB12: 0.98765432 | AC12: 1 | AD12: 0.97530864 | AE12: 1 | AF12: 0.4625 | AG12: 1 | AH12: 0.8961039 | AI12: NO
A13: D10 | B13: 0.3 | C13: 0.1 | D13: 0.2 | E13: 0.5 | F13: 0.1 | G13: 0.9 | H13: 0.55416667 | I13: 0.84810127 | J13: 0.42278481 | K13: 0.13055556 | L13: 0.05 | M13: 0.26216216 | N13: 0.515625 | O13: 0.075 | P13: 0.050632911 | Q13: 0.1 | R13: 0.9382716 | S13: 0.38271605 | T13: 0.96296296 | U13: 1 | V13: 1 | W13: 0.12345679 | X13: 0.96296296 | Y13: 0.95061728 | Z13: 0.75308642 | AA13: 0.35802469 | AB13: 0.98765432 | AC13: 1 | AD13: 0.97530864 | AE13: 1 | AF13: 0.4625 | AG13: 1 | AH13: 0.8961039 | AI13: YES
A14: D11 | B14: 1 | C14: 0 | D14: 0 | E14: 0 | F14: 0 | G14: 1 | H14: 0.5 | I14: 1 | J14: 0.6 | K14: 0 | L14: 0 | M14: 0.2 | N14: 0.5 | O14: 0 | P14: 0 | Q14: 0 | R14: 1 | S14: 0 | T14: 1 | U14: 1 | V14: 1 | W14: 0 | X14: 1 | Y14: 1 | Z14: 1 | AA14: 0 | AB14: 1 | AC14: 1 | AD14: 1 | AE14: 1 | AF14: 0 | AG14: 1 | AH14: 1 | AI14: YES
A15: D12 | B15: 0.5 | C15: 0 | D15: 0 | E15: 0 | F15: 0 | G15: 1 | H15: 0.5 | I15: 1 | J15: 0.6 | K15: 0 | L15: 0 | M15: 0.2 | N15: 0.5 | O15: 0 | P15: 0 | Q15: 0 | R15: 1 | S15: 0 | T15: 1 | U15: 1 | V15: 1 | W15: 0 | X15: 1 | Y15: 1 | Z15: 1 | AA15: 0 | AB15: 1 | AC15: 1 | AD15: 1 | AE15: 1 | AF15: 0 | AG15: 1 | AH15: 1 | AI15: NO
... A23: D20 | B23: 0.3 | C23: 0 | D23: 0 | E23: 0.7 | F23: 0 | G23: 1 | H23: 0.5 | I23: 1 | J23: 0.6 | K23: 0 | L23: 0 | M23: 0.2 | N23: 0.5 | O23: 0 | P23: 0 | Q23: 0 | R23: 1 | S23: 1 | T23: 1 | U23: 1 | V23: 1 | W23: 0 | X23: 1 | Y23: 1 | Z23: 1 | AA23: 1 | AB23: 1 | AC23: 1 | AD23: 1 | AE23: 1 | AF23: 0 | AG23: 1 | AH23: 1 | AI23: ?
A26: Probabilitas | B26: YES | C26: NO | D26: Total Data
A27: Probabilitas Kelas | B27: =COUNTIFS(AI4:AI19,"YES") -> 4 | C27: =COUNTIFS(AI4:AI23,"NO") -> 8 | D27: 12
A28: P(X) | B28: =B27/D27 -> 0.33333333 | C28: =C27/D27 -> 0.66666667
B30: A1 | C30: A2 | D30: A3 | E30: A4 | F30: A5 | G30: A6 | H30: A7 | I30: A8 | J30: A9 | K30: A10 | L30: A11 | M30: A12 | N30: A13 | O30: A14 | P30: A15 | Q30: A16 | R30: A17 | S30: A18 | T30: A19 | U30: A20 | V30: A21 | W30: A22 | X30: A23 | Y30: A24 | Z30: A25 | AA30: A26 | AB30: A27 | AC30: A28 | AD30: A29 | AE30: A30 | AF30: A31 | AG30: A32 | AH30: A33
A31: D13 | B31: 0.5 | C31: 0 | D31: 0 | E31: 0 | F31: 0 | G31: 1 | H31: 0.5 | I31: 1 | J31: 0.6 | K31: 0 | L31: 0 | M31: 0 | N31: 0.5 | O31: 0 | P31: 0 | Q31: 0 | R31: 1 | S31: 0 | T31: 1 | U31: 1 | V31: 1 | W31: 0 | X31: 1 | Y31: 1 | Z31: 1 | AA31: 0 | AB31: 1 | AC31: 1 | AD31: 1 | AE31: 1 | AF31: 0 | AG31: 1 | AH31: 1 | AI31: ?
A33: Atribut | C33: A1 | D33: A2 | E33: A3 | F33: A4 | G33: A5 | H33: A6 | I33: A7 | J33: A8 | K33: A9 | L33: A10 | M33: A11 | N33: A12 | O33: A13 | P33: A14 | Q33: A15 | R33: A16 | S33: A17 | T33: A18 | U33: A19 | V33: A20 | W33: A21 | X33: A22 | Y33: A23 | Z33: A24 | AA33: A25 | AB33: A26 | AC33: A27 | AD33: A28 | AE33: A29 | AF33: A30 | AG33: A31 | AH33: A32 | AI33: A33
A34: Yes | C34: =COUNTIFS(B$4:B$15,B31,$AI$4:$AI$15,"YES") -> 1 | D34: =COUNTIFS(C$4:C$15,C31,$AI$4:$AI$15,"YES") -> 2 | E34: =COUNTIFS(D$4:D$15,D31,$AI$4:$AI$15,"YES") -> 2 | F34: =COUNTIFS(E$4:E$15,E31,$AI$4:$AI$15,"YES") -> 1 | G34: =COUNTIFS(F$4:F$15,F31,$AI$4:$AI$15,"YES") -> 3 | H34: =COUNTIFS(G$4:G$15,G31,$AI$4:$AI$15,"YES") -> 3 | I34: =COUNTIFS(H$4:H$15,H31,$AI$4:$AI$15,"YES") -> 3 | J34: =COUNTIFS(I$4:I$15,I31,$AI$4:$AI$15,"YES") -> 3 | ... AI34: =COUNTIFS(AH$4:AH$15,AH31,$AI$4:$AI$15,"YES") -> 3
A35: No | C35: =COUNTIFS(B$4:B$15,B31,$AI$4:$AI$15,"No") -> 2 | D35: =COUNTIFS(C$4:C$15,C31,$AI$4:$AI$15,"No") -> 4 | E35: =COUNTIFS(D$4:D$15,D31,$AI$4:$AI$15,"No") -> 3 | F35: =COUNTIFS(E$4:E$15,E31,$AI$4:$AI$15,"No") -> 2 | G35: =COUNTIFS(F$4:F$15,F31,$AI$4:$AI$15,"No") -> 3 | H35: =COUNTIFS(G$4:G$15,G31,$AI$4:$AI$15,"No") -> 5 | I35: =COUNTIFS(H$4:H$15,H31,$AI$4:$AI$15,"No") -> 6 | J35: =COUNTIFS(I$4:I$15,I31,$AI$4:$AI$15,"No") -> 5 | ... AI35: =COUNTIFS(AH$4:AH$15,AH31,$AI$4:$AI$15,"No") -> 3
A36: P(X|CI) | B36: Yes | C36: =C34/$B$28 -> 3 | D36: =D34/$B$28 -> 6 | E36: =E34/$B$28 -> 6 | F36: =F34/$B$28 -> 3 | G36: =G34/$B$28 -> 9 | H36: =H34/$B$28 -> 9 | I36: =I34/$B$28 -> 9 | J36: =J34/$B$28 -> 9 | ... AI36: =AI34/$B$28 -> 9 | AJ36: =C36*D36*E36*F36*G36*H36*I36*J36*K36*L36*M36*N36*O36*P36*Q36*R36*S36*T36*U36*V36*W36*X36*Y36*Z36*AA36*AB36*AC36*AD36*AE36*AF36*AG36*AH36*AI36 -> 2.8228898e+29
B37: No | C37: =C35/$C$28 -> 3 | D37: =D35/$C$28 -> 6 | E37: =E35/$C$28 -> 4.5 | F37: =F35/$C$28 -> 3 | G37: =G35/$C$28 -> 4.5 | H37: =H35/$C$28 -> 7.5 | I37: =I35/$C$28 -> 9 | J37: =J35/$C$28 -> 7.5 | ... AI37: =AI35/$C$28 -> 4.5 | AJ37: =C37*D37*E37*F37*G37*H37*I37*J37*K37*L37*M37*N37*O37*P37*Q37*R37*S37*T37*U37*V37*W37*X37*Y37*Z37*AA37*AB37*AC37*AD37*AE37*AF37*AG37*AH37*AI37 -> 1.2930504e+28
A39: (P(X|H) * P(H)) / P(X) | C39: NEW KELAS
A40: Yes | B40: =AJ36*$B$28 -> 9.4096325e+28 | C40: =IF(B40>B41,A40, A41) -> Yes
A41: No | B41: =AJ37*$C$28 -> 8.6203357e+27
B43: A1 | C43: A2 | D43: A3 | E43: A4 | F43: A5 | G43: A6 | H43: A7 | I43: A8 | J43: A9 | K43: A10 | L43: A11 | M43: A12 | N43: A13 | O43: A14 | P43: A15 | Q43: A16 | R43: A17 | S43: A18 | T43: A19 | U43: A20 | V43: A21 | W43: A22 | X43: A23 | Y43: A24 | Z43: A25 | AA43: A26 | AB43: A27 | AC43: A28 | AD43: A29 | AE43: A30 | AF43: A31 | AG43: A32 | AH43: A33
A44: D14 | B44: 0 | C44: 0.1 | D44: 0.2 | E44: 0.5 | F44: 0.1 | G44: 0.9 | H44: 0.55416667 | I44: 0.84810127 | J44: 0.42278481 | K44: 0.13055556 | L44: 0.05 | M44: 0.26216216 | N44: 0.515625 | O44: 0.075 | P44: 0.050632911 | Q44: 0.1 | R44: 0.9382716 | S44: 0.38271605 | T44: 0.96296296 | U44: 1 | V44: 1 | W44: 0.12345679 | X44: 0.96296296 | Y44: 0.95061728 | Z44: 0.75308642 | AA44: 0.35802469 | AB44: 0.98765432 | AC44: 1 | AD44: 0.97530864 | AE44: 1 | AF44: 0.4625 | AG44: 1 | AH44: 0.8961039 | AI44: ?
A46: Atribut | C46: A1 | D46: A2 | E46: A3 | F46: A4 | G46: A5 | H46: A6 | I46: A7 | J46: A8 | K46: A9 | L46: A10 | M46: A11 | N46: A12 | O46: A13 | P46: A14 | Q46: A15 | R46: A16 | S46: A17 | T46: A18 | U46: A19 | V46: A20 | W46: A21 | X46: A22 | Y46: A23 | Z46: A24 | AA46: A25 | AB46: A26 | AC46: A27 | AD46: A28 | AE46: A29 | AF46: A30 | AG46: A31 | AH46: A32 | AI46: A33
A47: Yes | C47: =COUNTIFS(B$4:B$15,B44,$AI$4:$AI$15,"YES") -> 0 | D47: =COUNTIFS(C$4:C$15,C44,$AI$4:$AI$15,"YES") -> 1 | E47: =COUNTIFS(D$4:D$15,D44,$AI$4:$AI$15,"YES") -> 1 | F47: =COUNTIFS(E$4:E$15,E44,$AI$4:$AI$15,"YES") -> 1 | G47: =COUNTIFS(F$4:F$15,F44,$AI$4:$AI$15,"YES") -> 1 | H47: =COUNTIFS(G$4:G$15,G44,$AI$4:$AI$15,"YES") -> 1 | I47: =COUNTIFS(H$4:H$15,H44,$AI$4:$AI$15,"YES") -> 1 | J47: =COUNTIFS(I$4:I$15,I44,$AI$4:$AI$15,"YES") -> 1 | ... AI47: =COUNTIFS(AH$4:AH$15,AH44,$AI$4:$AI$15,"YES") -> 1
A48: No | C48: =COUNTIFS(B$4:B$15,B44,$AI$4:$AI$15,"No") -> 0 | D48: =COUNTIFS(C$4:C$15,C44,$AI$4:$AI$15,"No") -> 1 | E48: =COUNTIFS(D$4:D$15,D44,$AI$4:$AI$15,"No") -> 2 | F48: =COUNTIFS(E$4:E$15,E44,$AI$4:$AI$15,"No") -> 1 | G48: =COUNTIFS(F$4:F$15,F44,$AI$4:$AI$15,"No") -> 1 | H48: =COUNTIFS(G$4:G$15,G44,$AI$4:$AI$15,"No") -> 2 | I48: =COUNTIFS(H$4:H$15,H44,$AI$4:$AI$15,"No") -> 1 | J48: =COUNTIFS(I$4:I$15,I44,$AI$4:$AI$15,"No") -> 2 | ... AI48: =COUNTIFS(AH$4:AH$15,AH44,$AI$4:$AI$15,"No") -> 1
A49: P(X|CI) | B49: Yes | C49: =C47/$B$28 -> 0 | D49: =D47/$B$28 -> 3 | E49: =E47/$B$28 -> 3 | F49: =F47/$B$28 -> 3 | G49: =G47/$B$28 -> 3 | H49: =H47/$B$28 -> 3 | I49: =I47/$B$28 -> 3 | J49: =J47/$B$28 -> 3 | ... AI49: =AI47/$B$28 -> 3 | AJ49: =C49*D49*E49*F49*G49*H49*I49*J49*K49*L49*M49*N49*O49*P49*Q49*R49*S49*T49*U49*V49*W49*X49*Y49*Z49*AA49*AB49*AC49*AD49*AE49*AF49*AG49*AH49*AI49 -> 0
B50: No | C50: =C48/$C$28 -> 0 | D50: =D48/$C$28 -> 1.5 | E50: =E48/$C$28 -> 3 | F50: =F48/$C$28 -> 1.5 | G50: =G48/$C$28 -> 1.5 | H50: =H48/$C$28 -> 3 | I50: =I48/$C$28 -> 1.5 | J50: =J48/$C$28 -> 3 | ... AI50: =AI48/$C$28 -> 1.5 | AJ50: =C50*D50*E50*F50*G50*H50*I50*J50*K50*L50*M50*N50*O50*P50*Q50*R50*S50*T50*U50*V50*W50*X50*Y50*Z50*AA50*AB50*AC50*AD50*AE50*AF50*AG50*AH50*AI50 -> 0
A52: (P(X|H) * P(H)) / P(X) | C52: NEW KELAS
A53: Yes | B53: =AJ49*$B$28 -> 0 | C53: =IF(B53>B54,A53, A54) -> No
A54: No | B54: =AJ50*$C$28 -> 0
B56: A1 | C56: A2 | D56: A3 | E56: A4 | F56: A5 | G56: A6 | H56: A7 | I56: A8 | J56: A9 | K56: A10 | L56: A11 | M56: A12 | N56: A13 | O56: A14 | P56: A15 | Q56: A16 | R56: A17 | S56: A18 | T56: A19 | U56: A20 | V56: A21 | W56: A22 | X56: A23 | Y56: A24 | Z56: A25 | AA56: A26 | AB56: A27 | AC56: A28 | AD56: A29 | AE56: A30 | AF56: A31 | AG56: A32 | AH56: A33
A57: D15 | B57: 0 | C57: 0 | D57: 0 | E57: 0.7 | F57: 0.3 | G57: 1 | H57: 0.5 | I57: 1 | J57: 0.4 | K57: 0 | L57: 0 | M57: 0 | N57: 0.5 | O57: 0 | P57: 0 | Q57: 0 | R57: 1 | S57: 1 | T57: 1 | U57: 1 | V57: 1 | W57: 0 | X57: 1 | Y57: 1 | Z57: 1 | AA57: 1 | AB57: 1 | AC57: 1 | AD57: 1 | AE57: 1 | AF57: 0 | AG57: 1 | AH57: 1 | AI57: ?
...

Sheet C4.5
A1: No | B1: Atribut | D1: Sum Kasus | E1: Yes | F1: No | G1: Entropy | H1: Information Gain | I1: Split Info | J1: Gain Ratio
B2: Node 1 | C2: Kategori | D2: 10 | E2: =COUNTIF(NORMALISASI!A2:A11,"YES") -> 2 | F2: =COUNTIF(NORMALISASI!A2:A11,"NO") -> 8 | G2: =((-E2/D2)*IMLOG2(E2/D2)+(-F2/D2)*IMLOG2(F2/D2)) -> 0.72192809
A3: 1 | B3: Anggota ART | H3: =M9 -> 0 | I3: =-((D4/D2*(IMLOG2(D4/D2)))+(D5/D2*(IMLOG2(D5/D2)))+(D7/D2*(IMLOG2(D7/D2)))+(D8/D2*(IMLOG2(D8/D2)))) -> #NUM! | J3: =H3/I3 -> #NUM!
C4: 1 | D4: =COUNTIF(CLEANING!C3:C12,"1") -> 4 | E4: =COUNTIFS(CLEANING!C3:C12,"1",CLEANING!B3:B12,"YES") -> 0 | F4: =COUNTIFS(CLEANING!C3:C12,"1",CLEANING!B3:B12,"No") -> 0
C5: 2 | D5: =COUNTIF(CLEANING!C3:C12,"2") -> 4 | E5: =COUNTIFS(CLEANING!C3:C12,"2",CLEANING!B3:B12,"YES") -> 0 | F5: =COUNTIFS(CLEANING!C3:C12,"2",CLEANING!B3:B12,"No") -> 0
C6: 3 | D6: =COUNTIF(CLEANING!C3:C12,"3") -> 0 | E6: =COUNTIFS(CLEANING!C3:C12,"3",CLEANING!B3:B12,"YES") -> 0 | F6: =COUNTIFS(CLEANING!C3:C12,"3",CLEANING!B3:B12,"No") -> 0
C7: 4 | D7: =COUNTIF(CLEANING!C3:C12,"4") -> 0 | E7: =COUNTIFS(CLEANING!C3:C12,"4",CLEANING!B3:B12,"YES") -> 0 | F7: =COUNTIFS(CLEANING!C3:C12,"4",CLEANING!B3:B12,"No") -> 0 | G7: =((-E7/D7)*IMLOG2(E7/D7)+(-F7/D7)*IMLOG2(F7/D7)) -> #DIV/0!
C8: 5 | D8: =COUNTIF(CLEANING!C3:C12,"5") -> 0 | E8: =COUNTIFS(CLEANING!C3:C12,"5",CLEANING!B3:B12,"YES") -> 0 | F8: =COUNTIFS(CLEANING!C3:C12,"5",CLEANING!B3:B12,"No") -> 0
A9: 2 | B9: Status bangunan | H9: =(G2)-((D10/D2)*G10)-((D11/D2)*G11) -> #NUM! | I9: =-((D10/D2*(IMLOG2(D10/D2)))+(D11/D2*(IMLOG2(D11/D2)))) -> 0.77863215 | J9: =H9/I9 -> #NUM!
C10: 1 | D10: =COUNTIF(CLEANING!D3:D12,"1") -> 3 | E10: =COUNTIFS(CLEANING!D3:D12,"1",CLEANING!B3:B12,"YES") -> 0 | F10: =COUNTIFS(CLEANING!D3:D12,"1",CLEANING!B3:B12,"No") -> 0 | G10: =((-E10/D10)*IMLOG2(E10/D10)+(-F10/D10)*IMLOG2(F10/D10)) -> #NUM!
C11: 2 | D11: 8 | E11: =COUNTIFS(CLEANING!D3:D12,"2",CLEANING!B3:B12,"YES") -> 0 | F11: 7 | G11: =((-E11/D11)*IMLOG2(E11/D11)+(-F11/D11)*IMLOG2(F11/D11)) -> #NUM!
C12: 3 | D12: =COUNTIF(CLEANING!D3:D12,"3") -> 0 | E12: =COUNTIFS(CLEANING!D3:D12,"3",CLEANING!B3:B12,"YES") -> 0 | F12: =COUNTIFS(CLEANING!D3:D12,"3",CLEANING!B3:B12,"No") -> 0
C13: 4 | D13: =COUNTIF(CLEANING!D3:D12,"4") -> 1 | E13: =COUNTIFS(CLEANING!D3:D12,"4",CLEANING!B3:B12,"YES") -> 0 | F13: =COUNTIFS(CLEANING!D3:D12,"4",CLEANING!B3:B12,"No") -> 0
C14: 5 | D14: =COUNTIF(CLEANING!D3:D12,"5") -> 0 | E14: =COUNTIFS(CLEANING!D3:D12,"5",CLEANING!B3:B12,"YES") -> 0 | F14: =COUNTIFS(CLEANING!D3:D12,"5",CLEANING!B3:B12,"No") -> 0
A15: 3 | B15: Status lahan | H15: =(G2)-((D16/D2)*G16)-((D17/D2)*G17) -> #DIV/0! | I15: =-((D16/D2*(IMLOG2(D16/D2)))+(D17/D2*(IMLOG2(D17/D2)))) -> #NUM! | J15: =H15/I15 -> #DIV/0!
C16: 1 | D16: =COUNTIF(CLEANING!E3:E12,"1") -> 0 | E16: =COUNTIFS(CLEANING!E3:E12,"1",CLEANING!B3:B12,"YES") -> 0 | F16: =COUNTIFS(CLEANING!E3:E12,"1",CLEANING!B3:B12,"No") -> 0 | G16: =((-E16/D16)*IMLOG2(E16/D16)+(-F16/D16)*IMLOG2(F16/D16)) -> #DIV/0!
C17: 2 | D17: 8 | E17: =COUNTIFS(CLEANING!E3:E12,"2",CLEANING!B3:B12,"YES") -> 0 | F17: 7 | G17: =((-E17/D17)*IMLOG2(E17/D17)+(-F17/D17)*IMLOG2(F17/D17)) -> #NUM!
C18: 3 | D18: =COUNTIF(CLEANING!E3:E12,"3") -> 0 | E18: =COUNTIFS(CLEANING!E3:E12,"3",CLEANING!B3:B12,"YES") -> 0 | F18: =COUNTIFS(CLEANING!E3:E12,"3",CLEANING!B3:B12,"No") -> 0
C19: 4 | D19: =COUNTIF(CLEANING!E3:E12,"4") -> 0 | E19: =COUNTIFS(CLEANING!E3:E12,"4",CLEANING!B3:B12,"YES") -> 0 | F19: =COUNTIFS(CLEANING!E3:E12,"4",CLEANING!B3:B12,"No") -> 0
C20: 5 | D20: =COUNTIF(CLEANING!E3:E12,"5") -> 0 | E20: =COUNTIFS(CLEANING!E3:E12,"5",CLEANING!B3:B12,"YES") -> 0 | F20: =COUNTIFS(CLEANING!E3:E12,"5",CLEANING!B3:B12,"No") -> 0
A21: 4 | B21: Jenis Lantai | H21: =(G2)-((D27/D2)*G27) -> #DIV/0! | I21: =-((D23/D2*(IMLOG2(D23/D2)))+(D26/D2*(IMLOG2(D26/D2)))+(D27/D2*(IMLOG2(D29/D2)))) -> #NUM! | J21: =H21/I21 -> #DIV/0!
C22: 1 | D22: =COUNTIF(CLEANING!F3:F12,"1") -> 4 | E22: =COUNTIFS(CLEANING!F3:F12,"1",CLEANING!B3:B12,"YES") -> 0 | F22: =COUNTIFS(CLEANING!F3:F12,"1",CLEANING!B3:B12,"No") -> 0
C23: 2 | D23: =COUNTIF(CLEANING!F3:F12,"2") -> 0 | E23: =COUNTIFS(CLEANING!F3:F12,"2",CLEANING!B3:B12,"YES") -> 0 | F23: =COUNTIFS(CLEANING!F3:F12,"2",CLEANING!B3:B12,"No") -> 0
C24: 3 | D24: =COUNTIF(CLEANING!F3:F12,"3") -> 3 | E24: =COUNTIFS(CLEANING!F3:F12,"3",CLEANING!B3:B12,"YES") -> 0 | F24: =COUNTIFS(CLEANING!F3:F12,"3",CLEANING!B3:B12,"No") -> 0
C25: 4 | D25: =COUNTIF(CLEANING!F3:F12,"4") -> 0 | E25: =COUNTIFS(CLEANING!F3:F12,"4",CLEANING!B3:B12,"YES") -> 0 | F25: =COUNTIFS(CLEANING!F3:F12,"4",CLEANING!B3:B12,"No") -> 0
C26: 5 | D26: 6 | E26: =COUNTIFS(CLEANING!F3:F12,"5",CLEANING!B3:B12,"YES") -> 0 | F26: 6
C27: 6 | D27: =COUNTIF(CLEANING!F3:F12,"6") -> 0 | E27: =COUNTIFS(CLEANING!F3:F12,"6",CLEANING!B3:B12,"YES") -> 0 | F27: =COUNTIFS(CLEANING!F3:F12,"6",CLEANING!B3:B12,"No") -> 0 | G27: =((-E27/D27)*IMLOG2(E27/D27)+(-F27/D27)*IMLOG2(F27/D27)) -> #DIV/0!
C28: 7 | D28: =COUNTIF(CLEANING!F3:F12,"7") -> 1 | E28: =COUNTIFS(CLEANING!F3:F12,"7",CLEANING!B3:B12,"YES") -> 0 | F28: =COUNTIFS(CLEANING!F3:F12,"7",CLEANING!B3:B12,"No") -> 0
C29: 8 | D29: =COUNTIF(CLEANING!F3:F12,"8") -> 0 | E29: =COUNTIFS(CLEANING!F3:F12,"8",CLEANING!B3:B12,"YES") -> 0 | F29: =COUNTIFS(CLEANING!F3:F12,"8",CLEANING!B3:B12,"No") -> 0
C30: 9 | D30: =COUNTIF(CLEANING!F3:F12,"9") -> 0 | E30: =COUNTIFS(CLEANING!F3:F12,"9",CLEANING!B3:B12,"YES") -> 0 | F30: =COUNTIFS(CLEANING!F3:F12,"9",CLEANING!B3:B12,"No") -> 0
C31: 10 | D31: =COUNTIF(CLEANING!F3:F12,"10") -> 0 | E31: =COUNTIFS(CLEANING!F3:F12,"10",CLEANING!B3:B12,"YES") -> 0 | F31: =COUNTIFS(CLEANING!F3:F12,"10",CLEANING!B3:B12,"No") -> 0
A32: 5 | B32: Jenis Dinding | H32: =(G2)-((D35/D2)*G35) -> #DIV/0! | I32: =-((D33/D2*(IMLOG2(D33/D2)))+(D34/D2*(IMLOG2(D35/D2)))) -> #NUM! | J32: =H32/I32 -> #DIV/0!
C33: 1 | D33: =COUNTIF(CLEANING!G3:G12,"1") -> 1 | E33: =COUNTIFS(CLEANING!G3:G12,"1",CLEANING!B3:B12,"YES") -> 0 | F33: =COUNTIFS(CLEANING!G3:G12,"1",CLEANING!B3:B12,"No") -> 0
C34: 2 | D34: 6 | E34: =COUNTIFS(CLEANING!G3:G12,"2",CLEANING!B3:B12,"YES") -> 0 | F34: 6
C35: 3 | D35: =COUNTIF(CLEANING!G3:G12,"3") -> 0 | E35: =COUNTIFS(CLEANING!G3:G12,"3",CLEANING!B3:B12,"YES") -> 0 | F35: =COUNTIFS(CLEANING!G3:G12,"3",CLEANING!B3:B12,"No") -> 0 | G35: =((-E35/D35)*IMLOG2(E35/D35)+(-F35/D35)*IMLOG2(F35/D35)) -> #DIV/0!
C36: 4 | D36: =COUNTIF(CLEANING!G3:G12,"4") -> 0 | E36: =COUNTIFS(CLEANING!G3:G12,"4",CLEANING!B3:B12,"YES") -> 0 | F36: =COUNTIFS(CLEANING!G3:G12,"4",CLEANING!B3:B12,"No") -> 0
C37: 5 | D37: =COUNTIF(CLEANING!G3:G12,"5") -> 0 | E37: =COUNTIFS(CLEANING!G3:G12,"5",CLEANING!B3:B12,"YES") -> 0 | F37: =COUNTIFS(CLEANING!G3:G12,"5",CLEANING!B3:B12,"No") -> 0
C38: 6 | D38: =COUNTIF(CLEANING!G3:G12,"6") -> 0 | E38: =COUNTIFS(CLEANING!G3:G12,"6",CLEANING!B3:B12,"YES") -> 0 | F38: =COUNTIFS(CLEANING!G3:G12,"6",CLEANING!B3:B12,"No") -> 0
C39: 7 | D39: =COUNTIF(CLEANING!G3:G12,"7") -> 0 | E39: =COUNTIFS(CLEANING!G3:G12,"7",CLEANING!B3:B12,"YES") -> 0 | F39: =COUNTIFS(CLEANING!G3:G12,"7",CLEANING!B3:B12,"No") -> 0
A40: 6 | B40: Kondisi Dinding
...

Sheet KNN
A1: A1 | B1: A2 | C1: A3 | D1: A4 | E1: A5 | F1: A6 | G1: A7 | H1: A8 | I1: A9 | J1: A10 | K1: A11 | L1: A12 | M1: A13 | N1: A14 | O1: A15 | P1: A16 | Q1: A17 | R1: A18 | S1: A19 | T1: A20 | U1: A21 | V1: A22 | W1: A23 | X1: A24 | Y1: A25 | Z1: A26 | AA1: A27 | AB1: A28 | AC1: A29 | AD1: A30 | AE1: A31 | AF1: A32 | AG1: A33 | AH1: STATUS | AI1: KELAS ASAL | AJ1: PREDIKSI | AL1: DU1 | AM1: JARAK | AN1: URUTAN | AO1: KELAS | AQ1: DU 2 | AR1: JARAK | AS1: URUTAN | AT1: KELAS | AV1: DU3 | AW1: JARAK | AX1: UTUTAN | AY1: KELAS | BA1: DU4 | BB1: JARAK | BC1: URUTAN | BD1: KELAS | BF1: DU5 | BG1: JARAK | BH1: URUTAN | BI1: KELAS | BK1: DU6 | BL1: JARAK | BM1: URUTAN | BN1: KELAS | BP1: DU7 | BQ1: JARAK | BR1: URUTAN | BS1: KELAS | BU1: DU8 | BV1: JARAK | BW1: URUTAN | BX1: KELAS
A2: 0.5 | B2: 0 | C2: 0 | D2: 0.7 | E2: 0 | F2: 1 | G2: 0.5 | H2: 1 | I2: 0.6 | J2: 0.3 | K2: 0 | L2: 0.2 | M2: 0.5 | N2: 0 | O2: 0 | P2: 0 | Q2: 1 | R2: 1 | S2: 1 | T2: 1 | U2: 1 | V2: 0 | W2: 1 | X2: 1 | Y2: 1 | Z2: 0 | AA2: 1 | AB2: 1 | AC2: 1 | AD2: 1 | AE2: 0 | AF2: 1 | AG2: 1 | AH2: YES | AL2: YES | AM2: =SQRT((A2-$A$14)^2+(B2-$B$14)^2+(C2-$C$14)^2+(D2-$D$14)^2+(E2-$E$14)^2+(F2-$F$14)^2+(G2-$G$14)^2+(H2-$H$14)^2+(I2-$I$14)^2+(J2-$J$14)^2+(K2-$K$14)^2+(L2-$L$14)^2+(M2-$M$14)^2+(N2-$N$14)^2+(O2-$O$14)^2+(P2-$P$14)^2+(Q2-$Q$14)^2+(R2-$R$14)^2+(S2-$S$14)^2+(T2-$T$14)^2+(U2-$U$14)^2+(V2-$V$14)^2+(W2-$W$14)^2+(X2-$X$14)^2+(Y2-$Y$14)^2+(Z2-$Z$14)^2+(AA2-$AA$14)^2+(AB2-$AB$14)^2+(AC2-$AC$14)^2+(AD2-$AD$14)^2+(AE2-$AE$14)^2+(AF2-$AF$14)^2+(AG2-$AG$14)^2) -> 1.2727922 | AN2: A12 | AO2: NO | AQ2: NO | AR2: =SQRT((A2-$A$15)^2+(B2-$B$15)^2+(C2-$C$15)^2+(D2-$D$15)^2+(E2-$E$15)^2+(F2-$F$15)^2+(G2-$G$15)^2+(H2-$H$15)^2+(I2-$I$15)^2+(J2-$J$15)^2+(K2-$K$15)^2+(L2-$L$15)^2+(M2-$M$15)^2+(N2-$N$15)^2+(O2-$O$15)^2+(P2-$P$15)^2+(Q2-$Q$15)^2+(R2-$R$15)^2+(S2-$S$15)^2+(T2-$T$15)^2+(U2-$U$15)^2+(V2-$V$15)^2+(W2-$W$15)^2+(X2-$X$15)^2+(Y2-$Y$15)^2+(Z2-$Z$15)^2+(AA2-$AA$15)^2+(AB2-$AB$15)^2+(AC2-$AC$15)^2+(AD2-$AD$15)^2+(AE2-$AE$15)^2+(AF2-$AF$15)^2+(AG2-$AG$15)^2) -> 1.1361361 | AS2: A9 | AT2: NO | AV2: YES | AW2: =SQRT((A2-$A$16)^2+(B2-$B$16)^2+(C2-$C$16)^2+(D2-$D$16)^2+(E2-$E$16)^2+(F2-$F$16)^2+(G2-$G$16)^2+(H2-$H$16)^2+(I2-$I$16)^2+(J2-$J$16)^2+(K2-$K$16)^2+(L2-$L$16)^2+(M2-$M$16)^2+(N2-$N$16)^2+(O2-$O$16)^2+(P2-$P$16)^2+(Q2-$Q$16)^2+(R2-$R$16)^2+(S2-$S$16)^2+(T2-$T$16)^2+(U2-$U$16)^2+(V2-$V$16)^2+(W2-$W$16)^2+(X2-$X$16)^2+(Y2-$Y$16)^2+(Z2-$Z$16)^2+(AA2-$AA$16)^2+(AB2-$AB$16)^2+(AC2-$AC$16)^2+(AD2-$AD$16)^2+(AE2-$AE$16)^2+(AF2-$AF$16)^2+(AG2-$AG$16)^2) -> 1.2288206 | AX2: A9 | AY2: NO | BA2: NO | BB2: =SQRT((A2-$A$17)^2+(B2-$B$17)^2+(C2-$C$17)^2+(D2-$D$17)^2+(E2-$E$17)^2+(F2-$F$17)^2+(G2-$G$17)^2+(H2-$H$17)^2+(I2-$I$17)^2+(J2-$J$17)^2+(K2-$K$17)^2+(L2-$L$17)^2+(M2-$M$17)^2+(N2-$N$17)^2+(O2-$O$17)^2+(P2-$P$17)^2+(Q2-$Q$17)^2+(R2-$R$17)^2+(S2-$S$17)^2+(T2-$T$17)^2+(U2-$U$17)^2+(V2-$V$17)^2+(W2-$W$17)^2+(X2-$X$17)^2+(Y2-$Y$17)^2+(Z2-$Z$17)^2+(AA2-$AA$17)^2+(AB2-$AB$17)^2+(AC2-$AC$17)^2+(AD2-$AD$17)^2+(AE2-$AE$17)^2+(AF2-$AF$17)^2+(AG2-$AG$17)^2) -> 1.1361361 | BC2: A9 | BD2: NO | BF2: NO | BG2: =SQRT((A2-$A$18)^2+(B2-$B$18)^2+(C2-$C$18)^2+(D2-$D$18)^2+(E2-$E$18)^2+(F2-$F$18)^2+(G2-$G$18)^2+(H2-$H$18)^2+(I2-$I$18)^2+(J2-$J$18)^2+(K2-$K$18)^2+(L2-$L$18)^2+(M2-$M$18)^2+(N2-$N$18)^2+(O2-$O$18)^2+(P2-$P$18)^2+(Q2-$Q$18)^2+(R2-$R$18)^2+(S2-$S$18)^2+(T2-$T$18)^2+(U2-$U$18)^2+(V2-$V$18)^2+(W2-$W$18)^2+(X2-$X$18)^2+(Y2-$Y$18)^2+(Z2-$Z$18)^2+(AA2-$AA$18)^2+(AB2-$AB$18)^2+(AC2-$AC$18)^2+(AD2-$AD$18)^2+(AE2-$AE$18)^2+(AF2-$AF$18)^2+(AG2-$AG$18)^2) -> 1.1361361 | BH2: A9 | BI2: NO | BK2: NO | BL2: =SQRT((A2-$A$19)^2+(B2-$B$19)^2+(C2-$C$19)^2+(D2-$D$19)^2+(E2-$E$19)^2+(F2-$F$19)^2+(G2-$G$19)^2+(H2-$H$19)^2+(I2-$I$19)^2+(J2-$J$19)^2+(K2-$K$19)^2+(L2-$L$19)^2+(M2-$M$19)^2+(N2-$N$19)^2+(O2-$O$19)^2+(P2-$P$19)^2+(Q2-$Q$19)^2+(R2-$R$19)^2+(S2-$S$19)^2+(T2-$T$19)^2+(U2-$U$19)^2+(V2-$V$19)^2+(W2-$W$19)^2+(X2-$X$19)^2+(Y2-$Y$19)^2+(Z2-$Z$19)^2+(AA2-$AA$19)^2+(AB2-$AB$19)^2+(AC2-$AC$19)^2+(AD2-$AD$19)^2+(AE2-$AE$19)^2+(AF2-$AF$19)^2+(AG2-$AG$19)^2) -> 1.1361361 | BM2: A9 | BN2: NO | BP2: NO | BQ2: =SQRT((A2-$A$20)^2+(B2-$B$20)^2+(C2-$C$20)^2+(D2-$D$20)^2+(E2-$E$20)^2+(F2-$F$20)^2+(G2-$G$20)^2+(H2-$H$20)^2+(I2-$I$20)^2+(J2-$J$20)^2+(K2-$K$20)^2+(L2-$L$20)^2+(M2-$M$20)^2+(N2-$N$20)^2+(O2-$O$20)^2+(P2-$P$20)^2+(Q2-$Q$20)^2+(R2-$R$20)^2+(S2-$S$20)^2+(T2-$T$20)^2+(U2-$U$20)^2+(V2-$V$20)^2+(W2-$W$20)^2+(X2-$X$20)^2+(Y2-$Y$20)^2+(Z2-$Z$20)^2+(AA2-$AA$20)^2+(AB2-$AB$20)^2+(AC2-$AC$20)^2+(AD2-$AD$20)^2+(AE2-$AE$20)^2+(AF2-$AF$20)^2+(AG2-$AG$20)^2) -> 1.4899664 | BR2: A9 | BS2: NO | BU2: YES | BV2: =SQRT((A2-$A$21)^2+(B2-$B$21)^2+(C2-$C$21)^2+(D2-$D$21)^2+(E2-$E$21)^2+(F2-$F$21)^2+(G2-$G$21)^2+(H2-$H$21)^2+(I2-$I$21)^2+(J2-$J$21)^2+(K2-$K$21)^2+(L2-$L$21)^2+(M2-$M$21)^2+(N2-$N$21)^2+(O2-$O$21)^2+(P2-$P$21)^2+(Q2-$Q$21)^2+(R2-$R$21)^2+(S2-$S$21)^2+(T2-$T$21)^2+(U2-$U$21)^2+(V2-$V$21)^2+(W2-$W$21)^2+(X2-$X$21)^2+(Y2-$Y$21)^2+(Z2-$Z$21)^2+(AA2-$AA$21)^2+(AB2-$AB$21)^2+(AC2-$AC$21)^2+(AD2-$AD$21)^2+(AE2-$AE$21)^2+(AF2-$AF$21)^2+(AG2-$AG$21)^2) -> 1.0630146 | BW2: A1 | BX2: YES
A3: 0.3 | B3: 0.2 | C3: 0.3 | D3: 0 | E3: 0 | F3: 0 | G3: 0.5 | H3: 0 | I3: 0.4 | J3: 0 | K3: 0 | L3: 0.2 | M3: 0.5 | N3: 0 | O3: 0 | P3: 0 | Q3: 1 | R3: 0 | S3: 1 | T3: 1 | U3: 1 | V3: 0 | W3: 1 | X3: 1 | Y3: 1 | Z3: 0 | AA3: 1 | AB3: 1 | AC3: 1 | AD3: 1 | AE3: 1 | AF3: 1 | AG3: 0.5 | AH3: NO | AM3: =SQRT((A3-$A$14)^2+(B3-$B$14)^2+(C3-$C$14)^2+(D3-$D$14)^2+(E3-$E$14)^2+(F3-$F$14)^2+(G3-$G$14)^2+(H3-$H$14)^2+(I3-$I$14)^2+(J3-$J$14)^2+(K3-$K$14)^2+(L3-$L$14)^2+(M3-$M$14)^2+(N3-$N$14)^2+(O3-$O$14)^2+(P3-$P$14)^2+(Q3-$Q$14)^2+(R3-$R$14)^2+(S3-$S$14)^2+(T3-$T$14)^2+(U3-$U$14)^2+(V3-$V$14)^2+(W3-$W$14)^2+(X3-$X$14)^2+(Y3-$Y$14)^2+(Z3-$Z$14)^2+(AA3-$AA$14)^2+(AB3-$AB$14)^2+(AC3-$AC$14)^2+(AD3-$AD$14)^2+(AE3-$AE$14)^2+(AF3-$AF$14)^2+(AG3-$AG$14)^2) -> 1.8708287 | AN3: A11 | AO3: YES | AR3: =SQRT((A3-$A$15)^2+(B3-$B$15)^2+(C3-$C$15)^2+(D3-$D$15)^2+(E3-$E$15)^2+(F3-$F$15)^2+(G3-$G$15)^2+(H3-$H$15)^2+(I3-$I$15)^2+(J3-$J$15)^2+(K3-$K$15)^2+(L3-$L$15)^2+(M3-$M$15)^2+(N3-$N$15)^2+(O3-$O$15)^2+(P3-$P$15)^2+(Q3-$Q$15)^2+(R3-$R$15)^2+(S3-$S$15)^2+(T3-$T$15)^2+(U3-$U$15)^2+(V3-$V$15)^2+(W3-$W$15)^2+(X3-$X$15)^2+(Y3-$Y$15)^2+(Z3-$Z$15)^2+(AA3-$AA$15)^2+(AB3-$AB$15)^2+(AC3-$AC$15)^2+(AD3-$AD$15)^2+(AE3-$AE$15)^2+(AF3-$AF$15)^2+(AG3-$AG$15)^2) -> 1.6586112 | AS3: A10 | AT3: YES | AW3: =SQRT((A3-$A$16)^2+(B3-$B$16)^2+(C3-$C$16)^2+(D3-$D$16)^2+(E3-$E$16)^2+(F3-$F$16)^2+(G3-$G$16)^2+(H3-$H$16)^2+(I3-$I$16)^2+(J3-$J$16)^2+(K3-$K$16)^2+(L3-$L$16)^2+(M3-$M$16)^2+(N3-$N$16)^2+(O3-$O$16)^2+(P3-$P$16)^2+(Q3-$Q$16)^2+(R3-$R$16)^2+(S3-$S$16)^2+(T3-$T$16)^2+(U3-$U$16)^2+(V3-$V$16)^2+(W3-$W$16)^2+(X3-$X$16)^2+(Y3-$Y$16)^2+(Z3-$Z$16)^2+(AA3-$AA$16)^2+(AB3-$AB$16)^2+(AC3-$AC$16)^2+(AD3-$AD$16)^2+(AE3-$AE$16)^2+(AF3-$AF$16)^2+(AG3-$AG$16)^2) -> 2.4677925 | AX3: A10 | AY3: YES | BB3: =SQRT((A3-$A$17)^2+(B3-$B$17)^2+(C3-$C$17)^2+(D3-$D$17)^2+(E3-$E$17)^2+(F3-$F$17)^2+(G3-$G$17)^2+(H3-$H$17)^2+(I3-$I$17)^2+(J3-$J$17)^2+(K3-$K$17)^2+(L3-$L$17)^2+(M3-$M$17)^2+(N3-$N$17)^2+(O3-$O$17)^2+(P3-$P$17)^2+(Q3-$Q$17)^2+(R3-$R$17)^2+(S3-$S$17)^2+(T3-$T$17)^2+(U3-$U$17)^2+(V3-$V$17)^2+(W3-$W$17)^2+(X3-$X$17)^2+(Y3-$Y$17)^2+(Z3-$Z$17)^2+(AA3-$AA$17)^2+(AB3-$AB$17)^2+(AC3-$AC$17)^2+(AD3-$AD$17)^2+(AE3-$AE$17)^2+(AF3-$AF$17)^2+(AG3-$AG$17)^2) -> 1.6586112 | BC3: A10 | BD3: YES | BG3: =SQRT((A3-$A$18)^2+(B3-$B$18)^2+(C3-$C$18)^2+(D3-$D$18)^2+(E3-$E$18)^2+(F3-$F$18)^2+(G3-$G$18)^2+(H3-$H$18)^2+(I3-$I$18)^2+(J3-$J$18)^2+(K3-$K$18)^2+(L3-$L$18)^2+(M3-$M$18)^2+(N3-$N$18)^2+(O3-$O$18)^2+(P3-$P$18)^2+(Q3-$Q$18)^2+(R3-$R$18)^2+(S3-$S$18)^2+(T3-$T$18)^2+(U3-$U$18)^2+(V3-$V$18)^2+(W3-$W$18)^2+(X3-$X$18)^2+(Y3-$Y$18)^2+(Z3-$Z$18)^2+(AA3-$AA$18)^2+(AB3-$AB$18)^2+(AC3-$AC$18)^2+(AD3-$AD$18)^2+(AE3-$AE$18)^2+(AF3-$AF$18)^2+(AG3-$AG$18)^2) -> 1.6586112 | BH3: A10 | BI3: YES | BL3: =SQRT((A3-$A$19)^2+(B3-$B$19)^2+(C3-$C$19)^2+(D3-$D$19)^2+(E3-$E$19)^2+(F3-$F$19)^2+(G3-$G$19)^2+(H3-$H$19)^2+(I3-$I$19)^2+(J3-$J$19)^2+(K3-$K$19)^2+(L3-$L$19)^2+(M3-$M$19)^2+(N3-$N$19)^2+(O3-$O$19)^2+(P3-$P$19)^2+(Q3-$Q$19)^2+(R3-$R$19)^2+(S3-$S$19)^2+(T3-$T$19)^2+(U3-$U$19)^2+(V3-$V$19)^2+(W3-$W$19)^2+(X3-$X$19)^2+(Y3-$Y$19)^2+(Z3-$Z$19)^2+(AA3-$AA$19)^2+(AB3-$AB$19)^2+(AC3-$AC$19)^2+(AD3-$AD$19)^2+(AE3-$AE$19)^2+(AF3-$AF$19)^2+(AG3-$AG$19)^2) -> 1.6586112 | BM3: A10 | BN3: YES | BQ3: =SQRT((A3-$A$20)^2+(B3-$B$20)^2+(C3-$C$20)^2+(D3-$D$20)^2+(E3-$E$20)^2+(F3-$F$20)^2+(G3-$G$20)^2+(H3-$H$20)^2+(I3-$I$20)^2+(J3-$J$20)^2+(K3-$K$20)^2+(L3-$L$20)^2+(M3-$M$20)^2+(N3-$N$20)^2+(O3-$O$20)^2+(P3-$P$20)^2+(Q3-$Q$20)^2+(R3-$R$20)^2+(S3-$S$20)^2+(T3-$T$20)^2+(U3-$U$20)^2+(V3-$V$20)^2+(W3-$W$20)^2+(X3-$X$20)^2+(Y3-$Y$20)^2+(Z3-$Z$20)^2+(AA3-$AA$20)^2+(AB3-$AB$20)^2+(AC3-$AC$20)^2+(AD3-$AD$20)^2+(AE3-$AE$20)^2+(AF3-$AF$20)^2+(AG3-$AG$20)^2) -> 2.2271057 | BR3: A10 | BS3: YES | BV3: =SQRT((A3-$A$21)^2+(B3-$B$21)^2+(C3-$C$21)^2+(D3-$D$21)^2+(E3-$E$21)^2+(F3-$F$21)^2+(G3-$G$21)^2+(H3-$H$21)^2+(I3-$I$21)^2+(J3-$J$21)^2+(K3-$K$21)^2+(L3-$L$21)^2+(M3-$M$21)^2+(N3-$N$21)^2+(O3-$O$21)^2+(P3-$P$21)^2+(Q3-$Q$21)^2+(R3-$R$21)^2+(S3-$S$21)^2+(T3-$T$21)^2+(U3-$U$21)^2+(V3-$V$21)^2+(W3-$W$21)^2+(X3-$X$21)^2+(Y3-$Y$21)^2+(Z3-$Z$21)^2+(AA3-$AA$21)^2+(AB3-$AB$21)^2+(AC3-$AC$21)^2+(AD3-$AD$21)^2+(AE3-$AE$21)^2+(AF3-$AF$21)^2+(AG3-$AG$21)^2) -> 2.4310492 | BW3: A7 | BX3: NO
A4: 0.7 | B4: 0.2 | C4: 0.2 | D4: 0.7 | E4: 1 | F4: 0.9 | G4: 1 | H4: 0.84810127 | I4: 0.4 | J4: 0.5 | K4: 0.5 | L4: 0.26216216 | M4: 0.5 | N4: 1 | O4: 0.050632911 | P4: 0.5 | Q4: 1 | R4: 1 | S4: 1 | T4: 1 | U4: 1 | V4: 1 | W4: 1 | X4: 1 | Y4: 1 | Z4: 1 | AA4: 1 | AB4: 1 | AC4: 1 | AD4: 1 | AE4: 1 | AF4: 1 | AG4: 1 | AH4: NO | AM4: =SQRT((A4-$A$14)^2+(B4-$B$14)^2+(C4-$C$14)^2+(D4-$D$14)^2+(E4-$E$14)^2+(F4-$F$14)^2+(G4-$G$14)^2+(H4-$H$14)^2+(I4-$I$14)^2+(J4-$J$14)^2+(K4-$K$14)^2+(L4-$L$14)^2+(M4-$M$14)^2+(N4-$N$14)^2+(O4-$O$14)^2+(P4-$P$14)^2+(Q4-$Q$14)^2+(R4-$R$14)^2+(S4-$S$14)^2+(T4-$T$14)^2+(U4-$U$14)^2+(V4-$V$14)^2+(W4-$W$14)^2+(X4-$X$14)^2+(Y4-$Y$14)^2+(Z4-$Z$14)^2+(AA4-$AA$14)^2+(AB4-$AB$14)^2+(AC4-$AC$14)^2+(AD4-$AD$14)^2+(AE4-$AE$14)^2+(AF4-$AF$14)^2+(AG4-$AG$14)^2) -> 2.7846662 | AN4: A10 | AO4: YES | AR4: =SQRT((A4-$A$15)^2+(B4-$B$15)^2+(C4-$C$15)^2+(D4-$D$15)^2+(E4-$E$15)^2+(F4-$F$15)^2+(G4-$G$15)^2+(H4-$H$15)^2+(I4-$I$15)^2+(J4-$J$15)^2+(K4-$K$15)^2+(L4-$L$15)^2+(M4-$M$15)^2+(N4-$N$15)^2+(O4-$O$15)^2+(P4-$P$15)^2+(Q4-$Q$15)^2+(R4-$R$15)^2+(S4-$S$15)^2+(T4-$T$15)^2+(U4-$U$15)^2+(V4-$V$15)^2+(W4-$W$15)^2+(X4-$X$15)^2+(Y4-$Y$15)^2+(Z4-$Z$15)^2+(AA4-$AA$15)^2+(AB4-$AB$15)^2+(AC4-$AC$15)^2+(AD4-$AD$15)^2+(AE4-$AE$15)^2+(AF4-$AF$15)^2+(AG4-$AG$15)^2) -> 2.1991058 | AS4: A12 | AT4: NO | AW4: =SQRT((A4-$A$16)^2+(B4-$B$16)^2+(C4-$C$16)^2+(D4-$D$16)^2+(E4-$E$16)^2+(F4-$F$16)^2+(G4-$G$16)^2+(H4-$H$16)^2+(I4-$I$16)^2+(J4-$J$16)^2+(K4-$K$16)^2+(L4-$L$16)^2+(M4-$M$16)^2+(N4-$N$16)^2+(O4-$O$16)^2+(P4-$P$16)^2+(Q4-$Q$16)^2+(R4-$R$16)^2+(S4-$S$16)^2+(T4-$T$16)^2+(U4-$U$16)^2+(V4-$V$16)^2+(W4-$W$16)^2+(X4-$X$16)^2+(Y4-$Y$16)^2+(Z4-$Z$16)^2+(AA4-$AA$16)^2+(AB4-$AB$16)^2+(AC4-$AC$16)^2+(AD4-$AD$16)^2+(AE4-$AE$16)^2+(AF4-$AF$16)^2+(AG4-$AG$16)^2) -> 2.2725241 | AX4: A1 | AY4: YES | BB4: =SQRT((A4-$A$17)^2+(B4-$B$17)^2+(C4-$C$17)^2+(D4-$D$17)^2+(E4-$E$17)^2+(F4-$F$17)^2+(G4-$G$17)^2+(H4-$H$17)^2+(I4-$I$17)^2+(J4-$J$17)^2+(K4-$K$17)^2+(L4-$L$17)^2+(M4-$M$17)^2+(N4-$N$17)^2+(O4-$O$17)^2+(P4-$P$17)^2+(Q4-$Q$17)^2+(R4-$R$17)^2+(S4-$S$17)^2+(T4-$T$17)^2+(U4-$U$17)^2+(V4-$V$17)^2+(W4-$W$17)^2+(X4-$X$17)^2+(Y4-$Y$17)^2+(Z4-$Z$17)^2+(AA4-$AA$17)^2+(AB4-$AB$17)^2+(AC4-$AC$17)^2+(AD4-$AD$17)^2+(AE4-$AE$17)^2+(AF4-$AF$17)^2+(AG4-$AG$17)^2) -> 2.1991058 | BC4: A12 | BD4: NO | BG4: =SQRT((A4-$A$18)^2+(B4-$B$18)^2+(C4-$C$18)^2+(D4-$D$18)^2+(E4-$E$18)^2+(F4-$F$18)^2+(G4-$G$18)^2+(H4-$H$18)^2+(I4-$I$18)^2+(J4-$J$18)^2+(K4-$K$18)^2+(L4-$L$18)^2+(M4-$M$18)^2+(N4-$N$18)^2+(O4-$O$18)^2+(P4-$P$18)^2+(Q4-$Q$18)^2+(R4-$R$18)^2+(S4-$S$18)^2+(T4-$T$18)^2+(U4-$U$18)^2+(V4-$V$18)^2+(W4-$W$18)^2+(X4-$X$18)^2+(Y4-$Y$18)^2+(Z4-$Z$18)^2+(AA4-$AA$18)^2+(AB4-$AB$18)^2+(AC4-$AC$18)^2+(AD4-$AD$18)^2+(AE4-$AE$18)^2+(AF4-$AF$18)^2+(AG4-$AG$18)^2) -> 2.1991058 | BH4: A12 | BI4: NO | BL4: =SQRT((A4-$A$19)^2+(B4-$B$19)^2+(C4-$C$19)^2+(D4-$D$19)^2+(E4-$E$19)^2+(F4-$F$19)^2+(G4-$G$19)^2+(H4-$H$19)^2+(I4-$I$19)^2+(J4-$J$19)^2+(K4-$K$19)^2+(L4-$L$19)^2+(M4-$M$19)^2+(N4-$N$19)^2+(O4-$O$19)^2+(P4-$P$19)^2+(Q4-$Q$19)^2+(R4-$R$19)^2+(S4-$S$19)^2+(T4-$T$19)^2+(U4-$U$19)^2+(V4-$V$19)^2+(W4-$W$19)^2+(X4-$X$19)^2+(Y4-$Y$19)^2+(Z4-$Z$19)^2+(AA4-$AA$19)^2+(AB4-$AB$19)^2+(AC4-$AC$19)^2+(AD4-$AD$19)^2+(AE4-$AE$19)^2+(AF4-$AF$19)^2+(AG4-$AG$19)^2) -> 2.1991058 | BM4: A12 | BN4: NO | BQ4: =SQRT((A4-$A$20)^2+(B4-$B$20)^2+(C4-$C$20)^2+(D4-$D$20)^2+(E4-$E$20)^2+(F4-$F$20)^2+(G4-$G$20)^2+(H4-$H$20)^2+(I4-$I$20)^2+(J4-$J$20)^2+(K4-$K$20)^2+(L4-$L$20)^2+(M4-$M$20)^2+(N4-$N$20)^2+(O4-$O$20)^2+(P4-$P$20)^2+(Q4-$Q$20)^2+(R4-$R$20)^2+(S4-$S$20)^2+(T4-$T$20)^2+(U4-$U$20)^2+(V4-$V$20)^2+(W4-$W$20)^2+(X4-$X$20)^2+(Y4-$Y$20)^2+(Z4-$Z$20)^2+(AA4-$AA$20)^2+(AB4-$AB$20)^2+(AC4-$AC$20)^2+(AD4-$AD$20)^2+(AE4-$AE$20)^2+(AF4-$AF$20)^2+(AG4-$AG$20)^2) -> 2.9110764 | BR4: A12 | BS4: NO | BV4: =SQRT((A4-$A$21)^2+(B4-$B$21)^2+(C4-$C$21)^2+(D4-$D$21)^2+(E4-$E$21)^2+(F4-$F$21)^2+(G4-$G$21)^2+(H4-$H$21)^2+(I4-$I$21)^2+(J4-$J$21)^2+(K4-$K$21)^2+(L4-$L$21)^2+(M4-$M$21)^2+(N4-$N$21)^2+(O4-$O$21)^2+(P4-$P$21)^2+(Q4-$Q$21)^2+(R4-$R$21)^2+(S4-$S$21)^2+(T4-$T$21)^2+(U4-$U$21)^2+(V4-$V$21)^2+(W4-$W$21)^2+(X4-$X$21)^2+(Y4-$Y$21)^2+(Z4-$Z$21)^2+(AA4-$AA$21)^2+(AB4-$AB$21)^2+(AC4-$AC$21)^2+(AD4-$AD$21)^2+(AE4-$AE$21)^2+(AF4-$AF$21)^2+(AG4-$AG$21)^2) -> 2.3064044 | BW4: A10 | BX4: YES
A5: 0.5 | B5: 0 | C5: 0 | D5: 1 | E5: 0.3 | F5: 1 | G5: 0.5 | H5: 1 | I5: 0.6 | J5: 1 | K5: 0 | L5: 0 | M5: 1 | N5: 0 | O5: 0 | P5: 0 | Q5: 1 | R5: 1 | S5: 1 | T5: 1 | U5: 1 | V5: 0 | W5: 1 | X5: 1 | Y5: 0 | Z5: 1 | AA5: 1 | AB5: 1 | AC5: 1 | AD5: 1 | AE5: 0 | AF5: 1 | AG5: 1 | AH5: NO | AM5: =SQRT((A5-$A$14)^2+(B5-$B$14)^2+(C5-$C$14)^2+(D5-$D$14)^2+(E5-$E$14)^2+(F5-$F$14)^2+(G5-$G$14)^2+(H5-$H$14)^2+(I5-$I$14)^2+(J5-$J$14)^2+(K5-$K$14)^2+(L5-$L$14)^2+(M5-$M$14)^2+(N5-$N$14)^2+(O5-$O$14)^2+(P5-$P$14)^2+(Q5-$Q$14)^2+(R5-$R$14)^2+(S5-$S$14)^2+(T5-$T$14)^2+(U5-$U$14)^2+(V5-$V$14)^2+(W5-$W$14)^2+(X5-$X$14)^2+(Y5-$Y$14)^2+(Z5-$Z$14)^2+(AA5-$AA$14)^2+(AB5-$AB$14)^2+(AC5-$AC$14)^2+(AD5-$AD$14)^2+(AE5-$AE$14)^2+(AF5-$AF$14)^2+(AG5-$AG$14)^2) -> 2.310844 | AN5: A9 | AO5: NO | AR5: =SQRT((A5-$A$15)^2+(B5-$B$15)^2+(C5-$C$15)^2+(D5-$D$15)^2+(E5-$E$15)^2+(F5-$F$15)^2+(G5-$G$15)^2+(H5-$H$15)^2+(I5-$I$15)^2+(J5-$J$15)^2+(K5-$K$15)^2+(L5-$L$15)^2+(M5-$M$15)^2+(N5-$N$15)^2+(O5-$O$15)^2+(P5-$P$15)^2+(Q5-$Q$15)^2+(R5-$R$15)^2+(S5-$S$15)^2+(T5-$T$15)^2+(U5-$U$15)^2+(V5-$V$15)^2+(W5-$W$15)^2+(X5-$X$15)^2+(Y5-$Y$15)^2+(Z5-$Z$15)^2+(AA5-$AA$15)^2+(AB5-$AB$15)^2+(AC5-$AC$15)^2+(AD5-$AD$15)^2+(AE5-$AE$15)^2+(AF5-$AF$15)^2+(AG5-$AG$15)^2) -> 1.8295876 | AS5: A1 | AT5: YES | AW5: =SQRT((A5-$A$16)^2+(B5-$B$16)^2+(C5-$C$16)^2+(D5-$D$16)^2+(E5-$E$16)^2+(F5-$F$16)^2+(G5-$G$16)^2+(H5-$H$16)^2+(I5-$I$16)^2+(J5-$J$16)^2+(K5-$K$16)^2+(L5-$L$16)^2+(M5-$M$16)^2+(N5-$N$16)^2+(O5-$O$16)^2+(P5-$P$16)^2+(Q5-$Q$16)^2+(R5-$R$16)^2+(S5-$S$16)^2+(T5-$T$16)^2+(U5-$U$16)^2+(V5-$V$16)^2+(W5-$W$16)^2+(X5-$X$16)^2+(Y5-$Y$16)^2+(Z5-$Z$16)^2+(AA5-$AA$16)^2+(AB5-$AB$16)^2+(AC5-$AC$16)^2+(AD5-$AD$16)^2+(AE5-$AE$16)^2+(AF5-$AF$16)^2+(AG5-$AG$16)^2) -> 1.6217275 | AX5: A7 | AY5: NO | BB5: =SQRT((A5-$A$17)^2+(B5-$B$17)^2+(C5-$C$17)^2+(D5-$D$17)^2+(E5-$E$17)^2+(F5-$F$17)^2+(G5-$G$17)^2+(H5-$H$17)^2+(I5-$I$17)^2+(J5-$J$17)^2+(K5-$K$17)^2+(L5-$L$17)^2+(M5-$M$17)^2+(N5-$N$17)^2+(O5-$O$17)^2+(P5-$P$17)^2+(Q5-$Q$17)^2+(R5-$R$17)^2+(S5-$S$17)^2+(T5-$T$17)^2+(U5-$U$17)^2+(V5-$V$17)^2+(W5-$W$17)^2+(X5-$X$17)^2+(Y5-$Y$17)^2+(Z5-$Z$17)^2+(AA5-$AA$17)^2+(AB5-$AB$17)^2+(AC5-$AC$17)^2+(AD5-$AD$17)^2+(AE5-$AE$17)^2+(AF5-$AF$17)^2+(AG5-$AG$17)^2) -> 1.8295876 | BC5: A1 | BD5: YES | BG5: =SQRT((A5-$A$18)^2+(B5-$B$18)^2+(C5-$C$18)^2+(D5-$D$18)^2+(E5-$E$18)^2+(F5-$F$18)^2+(G5-$G$18)^2+(H5-$H$18)^2+(I5-$I$18)^2+(J5-$J$18)^2+(K5-$K$18)^2+(L5-$L$18)^2+(M5-$M$18)^2+(N5-$N$18)^2+(O5-$O$18)^2+(P5-$P$18)^2+(Q5-$Q$18)^2+(R5-$R$18)^2+(S5-$S$18)^2+(T5-$T$18)^2+(U5-$U$18)^2+(V5-$V$18)^2+(W5-$W$18)^2+(X5-$X$18)^2+(Y5-$Y$18)^2+(Z5-$Z$18)^2+(AA5-$AA$18)^2+(AB5-$AB$18)^2+(AC5-$AC$18)^2+(AD5-$AD$18)^2+(AE5-$AE$18)^2+(AF5-$AF$18)^2+(AG5-$AG$18)^2) -> 1.8295876 | BH5: A1 | BI5: YES | BL5: =SQRT((A5-$A$19)^2+(B5-$B$19)^2+(C5-$C$19)^2+(D5-$D$19)^2+(E5-$E$19)^2+(F5-$F$19)^2+(G5-$G$19)^2+(H5-$H$19)^2+(I5-$I$19)^2+(J5-$J$19)^2+(K5-$K$19)^2+(L5-$L$19)^2+(M5-$M$19)^2+(N5-$N$19)^2+(O5-$O$19)^2+(P5-$P$19)^2+(Q5-$Q$19)^2+(R5-$R$19)^2+(S5-$S$19)^2+(T5-$T$19)^2+(U5-$U$19)^2+(V5-$V$19)^2+(W5-$W$19)^2+(X5-$X$19)^2+(Y5-$Y$19)^2+(Z5-$Z$19)^2+(AA5-$AA$19)^2+(AB5-$AB$19)^2+(AC5-$AC$19)^2+(AD5-$AD$19)^2+(AE5-$AE$19)^2+(AF5-$AF$19)^2+(AG5-$AG$19)^2) -> 1.8295876 | BM5: A1 | BN5: YES | BQ5: =SQRT((A5-$A$20)^2+(B5-$B$20)^2+(C5-$C$20)^2+(D5-$D$20)^2+(E5-$E$20)^2+(F5-$F$20)^2+(G5-$G$20)^2+(H5-$H$20)^2+(I5-$I$20)^2+(J5-$J$20)^2+(K5-$K$20)^2+(L5-$L$20)^2+(M5-$M$20)^2+(N5-$N$20)^2+(O5-$O$20)^2+(P5-$P$20)^2+(Q5-$Q$20)^2+(R5-$R$20)^2+(S5-$S$20)^2+(T5-$T$20)^2+(U5-$U$20)^2+(V5-$V$20)^2+(W5-$W$20)^2+(X5-$X$20)^2+(Y5-$Y$20)^2+(Z5-$Z$20)^2+(AA5-$AA$20)^2+(AB5-$AB$20)^2+(AC5-$AC$20)^2+(AD5-$AD$20)^2+(AE5-$AE$20)^2+(AF5-$AF$20)^2+(AG5-$AG$20)^2) -> 1.8761663 | BR5: A11 | BS5: YES | BV5: =SQRT((A5-$A$21)^2+(B5-$B$21)^2+(C5-$C$21)^2+(D5-$D$21)^2+(E5-$E$21)^2+(F5-$F$21)^2+(G5-$G$21)^2+(H5-$H$21)^2+(I5-$I$21)^2+(J5-$J$21)^2+(K5-$K$21)^2+(L5-$L$21)^2+(M5-$M$21)^2+(N5-$N$21)^2+(O5-$O$21)^2+(P5-$P$21)^2+(Q5-$Q$21)^2+(R5-$R$21)^2+(S5-$S$21)^2+(T5-$T$21)^2+(U5-$U$21)^2+(V5-$V$21)^2+(W5-$W$21)^2+(X5-$X$21)^2+(Y5-$Y$21)^2+(Z5-$Z$21)^2+(AA5-$AA$21)^2+(AB5-$AB$21)^2+(AC5-$AC$21)^2+(AD5-$AD$21)^2+(AE5-$AE$21)^2+(AF5-$AF$21)^2+(AG5-$AG$21)^2) -> 1.584298 | BW5: A9 | BX5: NO
A6: 0.7 | B6: 0.2 | C6: 0.3 | D6: 0.7 | E6: 0 | F6: 1 | G6: 0.5 | H6: 1 | I6: 0.2 | J6: 0 | K6: 0 | L6: 0 | M6: 1 | N6: 0 | O6: 0 | P6: 0 | Q6: 1 | R6: 0 | S6: 1 | T6: 1 | U6: 1 | V6: 0 | W6: 1 | X6: 1 | Y6: 1 | Z6: 0 | AA6: 1 | AB6: 1 | AC6: 1 | AD6: 1 | AE6: 1 | AF6: 1 | AG6: 1 | AH6: YES | AM6: =SQRT((A6-$A$14)^2+(B6-$B$14)^2+(C6-$C$14)^2+(D6-$D$14)^2+(E6-$E$14)^2+(F6-$F$14)^2+(G6-$G$14)^2+(H6-$H$14)^2+(I6-$I$14)^2+(J6-$J$14)^2+(K6-$K$14)^2+(L6-$L$14)^2+(M6-$M$14)^2+(N6-$N$14)^2+(O6-$O$14)^2+(P6-$P$14)^2+(Q6-$Q$14)^2+(R6-$R$14)^2+(S6-$S$14)^2+(T6-$T$14)^2+(U6-$U$14)^2+(V6-$V$14)^2+(W6-$W$14)^2+(X6-$X$14)^2+(Y6-$Y$14)^2+(Z6-$Z$14)^2+(AA6-$AA$14)^2+(AB6-$AB$14)^2+(AC6-$AC$14)^2+(AD6-$AD$14)^2+(AE6-$AE$14)^2+(AF6-$AF$14)^2+(AG6-$AG$14)^2) -> 1.4387495 | AN6: A1 | AO6: YES | AR6: =SQRT((A6-$A$15)^2+(B6-$B$15)^2+(C6-$C$15)^2+(D6-$D$15)^2+(E6-$E$15)^2+(F6-$F$15)^2+(G6-$G$15)^2+(H6-$H$15)^2+(I6-$I$15)^2+(J6-$J$15)^2+(K6-$K$15)^2+(L6-$L$15)^2+(M6-$M$15)^2+(N6-$N$15)^2+(O6-$O$15)^2+(P6-$P$15)^2+(Q6-$Q$15)^2+(R6-$R$15)^2+(S6-$S$15)^2+(T6-$T$15)^2+(U6-$U$15)^2+(V6-$V$15)^2+(W6-$W$15)^2+(X6-$X$15)^2+(Y6-$Y$15)^2+(Z6-$Z$15)^2+(AA6-$AA$15)^2+(AB6-$AB$15)^2+(AC6-$AC$15)^2+(AD6-$AD$15)^2+(AE6-$AE$15)^2+(AF6-$AF$15)^2+(AG6-$AG$15)^2) -> 1.2833699 | AS6: A5 | AT6: YES | AW6: =SQRT((A6-$A$16)^2+(B6-$B$16)^2+(C6-$C$16)^2+(D6-$D$16)^2+(E6-$E$16)^2+(F6-$F$16)^2+(G6-$G$16)^2+(H6-$H$16)^2+(I6-$I$16)^2+(J6-$J$16)^2+(K6-$K$16)^2+(L6-$L$16)^2+(M6-$M$16)^2+(N6-$N$16)^2+(O6-$O$16)^2+(P6-$P$16)^2+(Q6-$Q$16)^2+(R6-$R$16)^2+(S6-$S$16)^2+(T6-$T$16)^2+(U6-$U$16)^2+(V6-$V$16)^2+(W6-$W$16)^2+(X6-$X$16)^2+(Y6-$Y$16)^2+(Z6-$Z$16)^2+(AA6-$AA$16)^2+(AB6-$AB$16)^2+(AC6-$AC$16)^2+(AD6-$AD$16)^2+(AE6-$AE$16)^2+(AF6-$AF$16)^2+(AG6-$AG$16)^2) -> 2 | AX6: A4 | AY6: NO | BB6: =SQRT((A6-$A$17)^2+(B6-$B$17)^2+(C6-$C$17)^2+(D6-$D$17)^2+(E6-$E$17)^2+(F6-$F$17)^2+(G6-$G$17)^2+(H6-$H$17)^2+(I6-$I$17)^2+(J6-$J$17)^2+(K6-$K$17)^2+(L6-$L$17)^2+(M6-$M$17)^2+(N6-$N$17)^2+(O6-$O$17)^2+(P6-$P$17)^2+(Q6-$Q$17)^2+(R6-$R$17)^2+(S6-$S$17)^2+(T6-$T$17)^2+(U6-$U$17)^2+(V6-$V$17)^2+(W6-$W$17)^2+(X6-$X$17)^2+(Y6-$Y$17)^2+(Z6-$Z$17)^2+(AA6-$AA$17)^2+(AB6-$AB$17)^2+(AC6-$AC$17)^2+(AD6-$AD$17)^2+(AE6-$AE$17)^2+(AF6-$AF$17)^2+(AG6-$AG$17)^2) -> 1.2833699 | BC6: A5 | BD6: YES | BG6: =SQRT((A6-$A$18)^2+(B6-$B$18)^2+(C6-$C$18)^2+(D6-$D$18)^2+(E6-$E$18)^2+(F6-$F$18)^2+(G6-$G$18)^2+(H6-$H$18)^2+(I6-$I$18)^2+(J6-$J$18)^2+(K6-$K$18)^2+(L6-$L$18)^2+(M6-$M$18)^2+(N6-$N$18)^2+(O6-$O$18)^2+(P6-$P$18)^2+(Q6-$Q$18)^2+(R6-$R$18)^2+(S6-$S$18)^2+(T6-$T$18)^2+(U6-$U$18)^2+(V6-$V$18)^2+(W6-$W$18)^2+(X6-$X$18)^2+(Y6-$Y$18)^2+(Z6-$Z$18)^2+(AA6-$AA$18)^2+(AB6-$AB$18)^2+(AC6-$AC$18)^2+(AD6-$AD$18)^2+(AE6-$AE$18)^2+(AF6-$AF$18)^2+(AG6-$AG$18)^2) -> 1.2833699 | BH6: A5 | BI6: YES | BL6: =SQRT((A6-$A$19)^2+(B6-$B$19)^2+(C6-$C$19)^2+(D6-$D$19)^2+(E6-$E$19)^2+(F6-$F$19)^2+(G6-$G$19)^2+(H6-$H$19)^2+(I6-$I$19)^2+(J6-$J$19)^2+(K6-$K$19)^2+(L6-$L$19)^2+(M6-$M$19)^2+(N6-$N$19)^2+(O6-$O$19)^2+(P6-$P$19)^2+(Q6-$Q$19)^2+(R6-$R$19)^2+(S6-$S$19)^2+(T6-$T$19)^2+(U6-$U$19)^2+(V6-$V$19)^2+(W6-$W$19)^2+(X6-$X$19)^2+(Y6-$Y$19)^2+(Z6-$Z$19)^2+(AA6-$AA$19)^2+(AB6-$AB$19)^2+(AC6-$AC$19)^2+(AD6-$AD$19)^2+(AE6-$AE$19)^2+(AF6-$AF$19)^2+(AG6-$AG$19)^2) -> 1.2833699 | BM6: A5 | BN6: YES | BQ6: =SQRT((A6-$A$20)^2+(B6-$B$20)^2+(C6-$C$20)^2+(D6-$D$20)^2+(E6-$E$20)^2+(F6-$F$20)^2+(G6-$G$20)^2+(H6-$H$20)^2+(I6-$I$20)^2+(J6-$J$20)^2+(K6-$K$20)^2+(L6-$L$20)^2+(M6-$M$20)^2+(N6-$N$20)^2+(O6-$O$20)^2+(P6-$P$20)^2+(Q6-$Q$20)^2+(R6-$R$20)^2+(S6-$S$20)^2+(T6-$T$20)^2+(U6-$U$20)^2+(V6-$V$20)^2+(W6-$W$20)^2+(X6-$X$20)^2+(Y6-$Y$20)^2+(Z6-$Z$20)^2+(AA6-$AA$20)^2+(AB6-$AB$20)^2+(AC6-$AC$20)^2+(AD6-$AD$20)^2+(AE6-$AE$20)^2+(AF6-$AF$20)^2+(AG6-$AG$20)^2) -> 1.6703293 | BR6: A1 | BS6: YES | BV6: =SQRT((A6-$A$21)^2+(B6-$B$21)^2+(C6-$C$21)^2+(D6-$D$21)^2+(E6-$E$21)^2+(F6-$F$21)^2+(G6-$G$21)^2+(H6-$H$21)^2+(I6-$I$21)^2+(J6-$J$21)^2+(K6-$K$21)^2+(L6-$L$21)^2+(M6-$M$21)^2+(N6-$N$21)^2+(O6-$O$21)^2+(P6-$P$21)^2+(Q6-$Q$21)^2+(R6-$R$21)^2+(S6-$S$21)^2+(T6-$T$21)^2+(U6-$U$21)^2+(V6-$V$21)^2+(W6-$W$21)^2+(X6-$X$21)^2+(Y6-$Y$21)^2+(Z6-$Z$21)^2+(AA6-$AA$21)^2+(AB6-$AB$21)^2+(AC6-$AC$21)^2+(AD6-$AD$21)^2+(AE6-$AE$21)^2+(AF6-$AF$21)^2+(AG6-$AG$21)^2) -> 1.933908 | BW6: A4 | BX6: NO
